Workbook
Name 품명: '초지 품명..'!$P$2:$P$76

Sheet 초지345(QLT03)
A1: [ 2026년1월~12월 검사결과 ]
O2: 단위 | Q2: mm | Y2: gf/100mm | AB2: mm | AC2: % | AI2: mm | AJ2: sec | AK2: cc/㎠/sec
A3: 월 | B3: 생산호기_설비코드 | C3: 생산호기 | D3: 날짜 | E3: 검사자 | F3: 반 | G3: 시간 | H3: 분 | I3: 기준평량 | J3: 지종 | K3: 합지LOTNO | L3: 자재코드 | M3: 품명 | N3: 설비코드 | O3: 적용 호기 | P3: 겹수 | Q3: 지폭 | R3: 평량 | S3: 백색도 | T3: 파열강도 | U3: MD-1 | V3: MD-2 | W3: MD-3 | X3: MD-4 | Y3: MD | Z3: CD | AA3: wet-cd | AB3: 흡수도 | AC3: 신장율 | AD3: 신1 | AE3: 신2 | AF3: 신3 | AG3: 신4 | AH3: 신장율2 | AI3: 두께 | AJ3: 물풀링성 | AK3: 투기도 | AL3: 핀홀상태 | AM3: 반점상태 | AN3: 형광검출 | AO3: 판정 | AP3: 비고 | AQ3: MD(3겹) | AR3: CD(3겹)
B4: MACH_CD | C4: MACH_NM | D4: MSRM_DATE | E4: MSRM_NM | F4: WRK_CLASS | G4: TIME_HOUR | H4: TIME_MIN | K4: LOT_NO | L4: MATNR | M4: MATNR_NM | N4: MACH_CD_TRA | O4: MACH_NM_TRA | Q4: WIDTH | R4: BS_WGT | S4: WHITE | T4: BURST | Y4: MD | Z4: CD | AA4: WET_CD | AB4: ABSORB | AH4: ELONG | AI4: THICK | AJ4: WET_SOLVE | AK4: AIR_PERM | AL4: PINHOLE | AM4: SPOT | AN4: FLUORO | AO4: FNL_JDGM | AP4: RMK
A5: 1월 | B5: =IFERROR(VLOOKUP(C5,'초지 품명..'!$I:$J,2,FALSE), "") -> TAA03 | C5: 초지3 | D5: 46023 | E5: 박용주 | F5: 4 | G5: 7 | H5: 0 | I5: 15.5 | J5: 고지 | K5: 260101B001 | L5: =IFERROR(VLOOKUP(M5, '초지 품명..'!$P:$Q, 2, FALSE), "") -> HRT-Z010002 | M5: 데코 (기획) 3P | N5: =IFERROR(VLOOKUP(O5, '초지 품명..'!$K:$L, 2, FALSE), "") -> TRA04 | O5: 가공4 | P5: 2 | Q5: 2930 | R5: 15.62 | S5: 78.7 | T5: 14160 | U5: 1140 | V5: 1230 | W5: 1300 | X5: 1310 | Y5: =IFERROR(AVERAGE(U5:X5),"") -> 1245 | Z5: 370 | AB5: 38 | AD5: 11.07 | AE5: 13 | AF5: 15.12 | AG5: 15.08 | AH5: =IFERROR(AVERAGE(표13[[#This Row],[신1]:[신4]]),"") -> 13.5675 | AI5: 0.224 | AL5: 양호 | AM5: 0개 | AO5: 합격 | AP5: 비고테스트
A6: 1월 | B6: =IFERROR(VLOOKUP(C6,'초지 품명..'!$I:$J,2,FALSE), "") -> TAA03 | C6: 초지3 | D6: 46023 | E6: 박용주 | F6: 4 | G6: 9 | H6: 0 | I6: 15.5 | J6: 고지 | K6: 260101B004 | L6: =IFERROR(VLOOKUP(M6, '초지 품명..'!$P:$Q, 2, FALSE), "") | N6: =IFERROR(VLOOKUP(O6, '초지 품명..'!$K:$L, 2, FALSE), "") -> TRA04 | O6: 가공4 | P6: 2 | Q6: 2930 | R6: 15.48 | S6: 79.2 | T6: 13655 | U6: 1230 | V6: 1270 | W6: 1280 | X6: 1420 | Y6: =IFERROR(AVERAGE(U6:X6),"") -> 1300 | Z6: 430 | AB6: 38 | AD6: 13.12 | AE6: 12.52 | AF6: 12.73 | AG6: 15.38 | AH6: =IFERROR(AVERAGE(표13[[#This Row],[신1]:[신4]]),"") -> 13.4375 | AI6: 0.219 | AL6: 양호 | AM6: 0개 | AO6: 합격
A7: 1월 | B7: =IFERROR(VLOOKUP(C7,'초지 품명..'!$I:$J,2,FALSE), "") -> TAA03 | C7: 초지3 | D7: 46030 | E7: 문종실 | F7: 3 | G7: 12 | H7: 40 | I7: 20 | J7: 고지 | K7: 260108B526 | L7: =IFERROR(VLOOKUP(M7, '초지 품명..'!$P:$Q, 2, FALSE), "") | N7: =IFERROR(VLOOKUP(O7, '초지 품명..'!$K:$L, 2, FALSE), "") -> 0 | O7: 판매용 | P7: 1 | Q7: 2830 | R7: 샘플없음 | Y7: =IFERROR(AVERAGE(U7:X7),"") | AH7: =IFERROR(AVERAGE(표13[[#This Row],[신1]:[신4]]),"")
A8: 1월 | B8: =IFERROR(VLOOKUP(C8,'초지 품명..'!$I:$J,2,FALSE), "") -> TAA03 | C8: 초지3 | D8: 46030 | E8: 문종실 | F8: 3 | G8: 14 | H8: 20 | I8: 15 | J8: 고지 | K8: 260108B531 | L8: =IFERROR(VLOOKUP(M8, '초지 품명..'!$P:$Q, 2, FALSE), "") | N8: =IFERROR(VLOOKUP(O8, '초지 품명..'!$K:$L, 2, FALSE), "") -> 0 | O8: 판매용 | P8: 2 | Q8: 2830 | R8: 14.9 | S8: 84.5 | T8: 12014 | U8: 1370 | V8: 1210 | W8: 1230 | X8: 1270 | Y8: =IFERROR(AVERAGE(U8:X8),"") -> 1270 | Z8: 650 | AB8: 38 | AD8: 19.8 | AE8: 17.23 | AF8: 16.64 | AG8: 17.59 | AH8: =IFERROR(AVERAGE(표13[[#This Row],[신1]:[신4]]),"") -> 17.815 | AI8: 0.228 | AJ8: 11.07 | AL8: 양호 | AM8: 0개 | AO8: 합격
A9: 1월 | B9: =IFERROR(VLOOKUP(C9,'초지 품명..'!$I:$J,2,FALSE), "") -> TAA04 | C9: 초지4 | D9: 46031 | E9: 문종실 | F9: 3 | K9: (07:00~18:30) | L9: =IFERROR(VLOOKUP(M9, '초지 품명..'!$P:$Q, 2, FALSE), "") | N9: =IFERROR(VLOOKUP(O9, '초지 품명..'!$K:$L, 2, FALSE), "") -> 0 | O9: 정비 운휴 | Y9: =IFERROR(AVERAGE(U9:X9),"")
A10: 1월 | B10: =IFERROR(VLOOKUP(C10,'초지 품명..'!$I:$J,2,FALSE), "") -> TAA04 | C10: 초지4 | D10: 46031 | E10: 권혜림 | F10: 1 | G10: 19 | H10: 40 | I10: 14.2 | K10: 260109C002 | L10: =IFERROR(VLOOKUP(M10, '초지 품명..'!$P:$Q, 2, FALSE), "") | N10: =IFERROR(VLOOKUP(O10, '초지 품명..'!$K:$L, 2, FALSE), "") -> TRA04 | O10: 가공4 | P10: 3 | Q10: 2930 | R10: 샘플없음 | Y10: =IFERROR(AVERAGE(U10:X10),"") | AH10: =IFERROR(AVERAGE(표13[[#This Row],[신1]:[신4]]),"")
A11: 1월 | B11: =IFERROR(VLOOKUP(C11,'초지 품명..'!$I:$J,2,FALSE), "") -> TAA04 | C11: 초지4 | D11: 46033 | E11: 송지숙 | F11: 2 | G11: 7 | H11: 0 | I11: 14.2 | K11: 260111C001 | L11: =IFERROR(VLOOKUP(M11, '초지 품명..'!$P:$Q, 2, FALSE), "") | N11: =IFERROR(VLOOKUP(O11, '초지 품명..'!$K:$L, 2, FALSE), "") -> TRA03 | O11: 가공3 | P11: 3 | Q11: 2950 | R11: 13.75 | S11: 87.4 | T11: 15304 | U11: 1410 | V11: 1410 | W11: 1370 | X11: 1100 | Y11: =IFERROR(AVERAGE(U11:X11),"") -> 1322.5 | Z11: 530 | AB11: 45 | AD11: 13.14 | AE11: 14.02 | AF11: 18.12 | AG11: 14.53 | AH11: =IFERROR(AVERAGE(표13[[#This Row],[신1]:[신4]]),"") -> 14.9525 | AI11: 0.206 | AL11: 양호 | AM11: 0개 | AN11: 불검출 | AO11: 합격
A12: 1월 | B12: =IFERROR(VLOOKUP(C12,'초지 품명..'!$I:$J,2,FALSE), "") -> TAA04 | C12: 초지4 | D12: 46035 | E12: 박용주 | F12: 4 | K12: (16:00~18:30) | L12: =IFERROR(VLOOKUP(M12, '초지 품명..'!$P:$Q, 2, FALSE), "") | N12: =IFERROR(VLOOKUP(O12, '초지 품명..'!$K:$L, 2, FALSE), "") -> 0 | O12: 급전 운휴 | Y12: =IFERROR(AVERAGE(U12:X12),"") | AH12: =IFERROR(AVERAGE(표13[[#This Row],[신1]:[신4]]),"")
A13: 1월 | B13: =IFERROR(VLOOKUP(C13,'초지 품명..'!$I:$J,2,FALSE), "") -> TAA04 | C13: 초지4 | D13: 46035 | E13: 박용주 | F13: 4 | G13: 19 | H13: 40 | I13: 21.5 | K13: 260113C013 | L13: =IFERROR(VLOOKUP(M13, '초지 품명..'!$P:$Q, 2, FALSE), "") | N13: =IFERROR(VLOOKUP(O13, '초지 품명..'!$K:$L, 2, FALSE), "") -> TRA03 | O13: 가공3 | P13: 3 | Q13: 2960 | R13: 샘플없음 | Y13: =IFERROR(AVERAGE(U13:X13),"") | AH13: =IFERROR(AVERAGE(표13[[#This Row],[신1]:[신4]]),"")
A14: 1월 | B14: =IFERROR(VLOOKUP(C14,'초지 품명..'!$I:$J,2,FALSE), "") -> TAA05 | C14: 초지5 | D14: 46035 | E14: 박용주 | F14: 4 | K14: (15:45~18:30) | L14: =IFERROR(VLOOKUP(M14, '초지 품명..'!$P:$Q, 2, FALSE), "") | N14: =IFERROR(VLOOKUP(O14, '초지 품명..'!$K:$L, 2, FALSE), "") -> 0 | O14: 급전 운휴 | Y14: =IFERROR(AVERAGE(U14:X14),"") | AH14: =IFERROR(AVERAGE(표13[[#This Row],[신1]:[신4]]),"")
A15: 1월 | B15: =IFERROR(VLOOKUP(C15,'초지 품명..'!$I:$J,2,FALSE), "") -> TAA05 | C15: 초지5 | D15: 46035 | E15: 박용주 | F15: 4 | K15: (19:30~23:30) | L15: =IFERROR(VLOOKUP(M15, '초지 품명..'!$P:$Q, 2, FALSE), "") | N15: =IFERROR(VLOOKUP(O15, '초지 품명..'!$K:$L, 2, FALSE), "") -> 0 | O15: 급전 운휴 | Y15: =IFERROR(AVERAGE(U15:X15),"") | AH15: =IFERROR(AVERAGE(표13[[#This Row],[신1]:[신4]]),"")
B16: =IFERROR(VLOOKUP(C16,'초지 품명..'!$I:$J,2,FALSE), "") -> TAA05 | C16: 초지5 | D16: 46035 | E16: 문종실 | F16: 3 | G16: 24 | H16: 0 | I16: 15.1 | K16: 260113D019 | L16: =IFERROR(VLOOKUP(M16, '초지 품명..'!$P:$Q, 2, FALSE), "") | N16: =IFERROR(VLOOKUP(O16, '초지 품명..'!$K:$L, 2, FALSE), "") -> TRA06 | O16: 가공6 | P16: 3 | Q16: 2950 | R16: 15.18 | S16: 88.1 | T16: 12415 | U16: 1110 | V16: 1500 | W16: 1230 | Y16: =IFERROR(AVERAGE(U16:X16),"") -> 1280 | Z16: 410 | AB16: 49 | AD16: 18.72 | AE16: 18.27 | AF16: 20.02 | AH16: =IFERROR(AVERAGE(표13[[#This Row],[신1]:[신4]]),"") -> 19.003333 | AI16: 0.204 | AL16: 양호 | AM16: 0개 | AN16: 불검출 | AO16: 합격
A17: 2월 | B17: =IFERROR(VLOOKUP(C17,'초지 품명..'!$I:$J,2,FALSE), "") -> TAA04 | C17: 초지4 | D17: 46077 | E17: 권혜림 | F17: 1 | G17: 14 | H17: 40 | I17: 14.7 | K17: 260224C009 | L17: =IFERROR(VLOOKUP(M17, '초지 품명..'!$P:$Q, 2, FALSE), "") | N17: =IFERROR(VLOOKUP(O17, '초지 품명..'!$K:$L, 2, FALSE), "") -> TRA05 | O17: 가공5 | P17: 3 | Q17: 2950 | R17: 14.65 | S17: 86.9 | T17: 13397 | U17: 1420 | V17: 1200 | W17: 1450 | Y17: =IFERROR(AVERAGE(U17:X17),"") -> 1356.6667 | Z17: 460 | AB17: 47 | AD17: 15.02 | AE17: 14.71 | AF17: 15.33 | AH17: =IFERROR(AVERAGE(표13[[#This Row],[신1]:[신4]]),"") -> 15.02 | AI17: 0.215 | AL17: 양호 | AM17: 0개 | AN17: 불검출 | AO17: 합격
A18: 2월 | B18: =IFERROR(VLOOKUP(C18,'초지 품명..'!$I:$J,2,FALSE), "") -> TAA04 | C18: 초지4 | D18: 46077 | E18: 박용주 | F18: 4 | G18: 18 | H18: 0 | I18: 14.7 | K18: 260224C013 | L18: =IFERROR(VLOOKUP(M18, '초지 품명..'!$P:$Q, 2, FALSE), "") | N18: =IFERROR(VLOOKUP(O18, '초지 품명..'!$K:$L, 2, FALSE), "") -> TRA05 | O18: 가공5 | P18: 3 | Q18: 2950 | R18: 14.9 | S18: 87 | T18: 15352 | U18: 1350 | V18: 1430 | W18: 1150 | Y18: =IFERROR(AVERAGE(U18:X18),"") -> 1310 | Z18: 470 | AB18: 44 | AD18: 16.29 | AE18: 17.63 | AF18: 16.58 | AH18: =IFERROR(AVERAGE(표13[[#This Row],[신1]:[신4]]),"") -> 16.833333 | AI18: 0.205 | AL18: 양호 | AM18: 0개 | AN18: 불검출 | AO18: 합격
A19: 2월 | B19: =IFERROR(VLOOKUP(C19,'초지 품명..'!$I:$J,2,FALSE), "") -> TAA05 | C19: 초지5 | D19: 46077 | E19: 권혜림 | F19: 1 | G19: 8 | H19: 50 | I19: 15.1 | K19: 260224D004 | L19: =IFERROR(VLOOKUP(M19, '초지 품명..'!$P:$Q, 2, FALSE), "") | N19: =IFERROR(VLOOKUP(O19, '초지 품명..'!$K:$L, 2, FALSE), "") -> TRA06 | O19: 가공6 | P19: 3 | Q19: 2950 | R19: 15.02 | S19: 88.3 | T19: 13679 | U19: 1360 | V19: 1480 | W19: 1400 | Y19: =IFERROR(AVERAGE(U19:X19),"") -> 1413.3333 | Z19: 510 | AB19: 45 | AD19: 14.25 | AE19: 14.44 | AF19: 13.97 | AH19: =IFERROR(AVERAGE(표13[[#This Row],[신1]:[신4]]),"") -> 14.22 | AI19: 0.191 | AL19: 양호 | AM19: 0개 | AN19: 불검출 | AO19: 합격
A20: 2월 | B20: =IFERROR(VLOOKUP(C20,'초지 품명..'!$I:$J,2,FALSE), "") -> TAA05 | C20: 초지5 | D20: 46077 | E20: 권혜림 | F20: 1 | G20: 11 | H20: 40 | I20: 15.1 | K20: 260224D008 | L20: =IFERROR(VLOOKUP(M20, '초지 품명..'!$P:$Q, 2, FALSE), "") | N20: =IFERROR(VLOOKUP(O20, '초지 품명..'!$K:$L, 2, FALSE), "") -> TRA06 | O20: 가공6 | P20: 3 | Q20: 2950 | R20: 14.83 | S20: 88.5 | T20: 12287 | U20: 1210 | V20: 1500 | W20: 1360 | Y20: =IFERROR(AVERAGE(U20:X20),"") -> 1356.6667 | Z20: 470 | AB20: 45 | AD20: 11.41 | AE20: 12.47 | AF20: 13.07 | AH20: =IFERROR(AVERAGE(표13[[#This Row],[신1]:[신4]]),"") -> 12.316667 | AI20: 0.19 | AL20: 양호 | AM20: 0개 | AN20: 불검출 | AO20: 합격
A21: 2월 | B21: =IFERROR(VLOOKUP(C21,'초지 품명..'!$I:$J,2,FALSE), "") -> TAA05 | C21: 초지5 | D21: 46077 | E21: 권혜림 | F21: 1 | G21: 14 | H21: 40 | I21: 15.1 | K21: 260224D012 | L21: =IFERROR(VLOOKUP(M21, '초지 품명..'!$P:$Q, 2, FALSE), "") | N21: =IFERROR(VLOOKUP(O21, '초지 품명..'!$K:$L, 2, FALSE), "") -> TRA06 | O21: 가공6 | P21: 3 | Q21: 2950 | R21: 14.86 | S21: 88.5 | T21: 12685 | U21: 1440 | V21: 1300 | W21: 1420 | Y21: =IFERROR(AVERAGE(U21:X21),"") -> 1386.6667 | Z21: 460 | AB21: 46 | AD21: 15.36 | AE21: 16.74 | AF21: 12.99 | AH21: =IFERROR(AVERAGE(표13[[#This Row],[신1]:[신4]]),"") -> 15.03 | AI21: 0.187 | AL21: 양호 | AM21: 0개 | AN21: 불검출 | AO21: 합격
A22: 2월 | B22: =IFERROR(VLOOKUP(C22,'초지 품명..'!$I:$J,2,FALSE), "") -> TAA04 | C22: 초지4 | D22: 46077 | E22: 박용주 | F22: 4 | G22: 21 | H22: 20 | I22: 14.7 | K22: 260224C017 | L22: =IFERROR(VLOOKUP(M22, '초지 품명..'!$P:$Q, 2, FALSE), "") | N22: =IFERROR(VLOOKUP(O22, '초지 품명..'!$K:$L, 2, FALSE), "") -> TRA05 | O22: 가공5 | P22: 3 | Q22: 2950 | R22: 14.62 | S22: 86.9 | T22: 16870 | U22: 1150 | V22: 1270 | W22: 1080 | Y22: =IFERROR(AVERAGE(U22:X22),"") -> 1166.6667 | Z22: 450 | AB22: 43 | AD22: 16.92 | AE22: 17.17 | AF22: 14.39 | AH22: =IFERROR(AVERAGE(표13[[#This Row],[신1]:[신4]]),"") -> 16.16 | AI22: 0.219 | AL22: 양호 | AM22: 0개 | AN22: 불검출 | AO22: 합격
A23: 3월 | B23: =IFERROR(VLOOKUP(C23,'초지 품명..'!$I:$J,2,FALSE), "") -> TAA04 | C23: 초지4 | D23: 46085 | E23: 송지숙 | F23: 2 | G23: 20 | H23: 30 | I23: 14.2 | K23: 260304C013 | L23: =IFERROR(VLOOKUP(M23, '초지 품명..'!$P:$Q, 2, FALSE), "") | N23: =IFERROR(VLOOKUP(O23, '초지 품명..'!$K:$L, 2, FALSE), "") -> TRA03 | O23: 가공3 | P23: 3 | Q23: 2950 | R23: 14.12 | S23: 86.9 | T23: 14336 | U23: 1370 | V23: 1210 | W23: 1270 | Y23: =IFERROR(AVERAGE(U23:X23),"") -> 1283.3333 | Z23: 520 | AB23: 47 | AD23: 16.12 | AE23: 12.47 | AF23: 14.82 | AH23: =IFERROR(AVERAGE(표13[[#This Row],[신1]:[신4]]),"") -> 14.47 | AI23: 0.201 | AL23: 양호 | AM23: 0개 | AN23: 불검출 | AO23: 합격
A24: 3월 | B24: =IFERROR(VLOOKUP(C24,'초지 품명..'!$I:$J,2,FALSE), "") -> TAA04 | C24: 초지4 | D24: 46085 | E24: 권혜림 | F24: 1 | G24: 24 | H24: 0 | I24: 14.2 | K24: 260304C016 | L24: =IFERROR(VLOOKUP(M24, '초지 품명..'!$P:$Q, 2, FALSE), "") -> HRT-Z030004 | M24: 촉앤감 미용 | N24: =IFERROR(VLOOKUP(O24, '초지 품명..'!$K:$L, 2, FALSE), "") -> TRA03 | O24: 가공3 | P24: 3 | Q24: 2950 | R24: 1 | S24: 1 | T24: 1 | U24: 1 | V24: 1 | W24: 1 | X24: 1 | Y24: =IFERROR(AVERAGE(U24:X24),"") -> 1 | Z24: 1 | AA24: 1 | AB24: 1 | AD24: 1 | AE24: 1 | AG24: 1 | AH24: 1 | AI24: 1 | AJ24: 1 | AK24: 1 | AL24: 양호 | AM24: 3개 | AN24: 유 | AO24: 불합격 | AP24: insert 테스트
A25: 3월 | B25: =IFERROR(VLOOKUP(C25,'초지 품명..'!$I:$J,2,FALSE), "") -> TAA05 | C25: 초지5 | D25: 46085 | E25: 권혜림 | F25: 1 | G25: 3 | H25: 10 | I25: 15.1 | K25: 260304D032 | L25: =IFERROR(VLOOKUP(M25, '초지 품명..'!$P:$Q, 2, FALSE), "") | N25: =IFERROR(VLOOKUP(O25, '초지 품명..'!$K:$L, 2, FALSE), "") -> TRA06 | O25: 가공6 | P25: 3 | Q25: 2950 | Y25: =IFERROR(AVERAGE(U25:X25),"")
B26: =IFERROR(VLOOKUP(C26,'초지 품명..'!$I:$J,2,FALSE), "") | L26: =IFERROR(VLOOKUP(M26, '초지 품명..'!$P:$Q, 2, FALSE), "") | N26: =IFERROR(VLOOKUP(O26, '초지 품명..'!$K:$L, 2, FALSE), "") | Y26: =IFERROR(AVERAGE(U26:X26),"")
B27: =IFERROR(VLOOKUP(C27,'초지 품명..'!$I:$J,2,FALSE), "") | L27: =IFERROR(VLOOKUP(M27, '초지 품명..'!$P:$Q, 2, FALSE), "") | N27: =IFERROR(VLOOKUP(O27, '초지 품명..'!$K:$L, 2, FALSE), "") | Y27: =IFERROR(AVERAGE(U27:X27),"")
B28: =IFERROR(VLOOKUP(C28,'초지 품명..'!$I:$J,2,FALSE), "") | L28: =IFERROR(VLOOKUP(M28, '초지 품명..'!$P:$Q, 2, FALSE), "") | N28: =IFERROR(VLOOKUP(O28, '초지 품명..'!$K:$L, 2, FALSE), "") | Y28: =IFERROR(AVERAGE(U28:X28),"")
B29: =IFERROR(VLOOKUP(C29,'초지 품명..'!$I:$J,2,FALSE), "") | L29: =IFERROR(VLOOKUP(M29, '초지 품명..'!$P:$Q, 2, FALSE), "") | N29: =IFERROR(VLOOKUP(O29, '초지 품명..'!$K:$L, 2, FALSE), "") | Y29: =IFERROR(AVERAGE(U29:X29),"")
B30: =IFERROR(VLOOKUP(C30,'초지 품명..'!$I:$J,2,FALSE), "") | L30: =IFERROR(VLOOKUP(M30, '초지 품명..'!$P:$Q, 2, FALSE), "") | N30: =IFERROR(VLOOKUP(O30, '초지 품명..'!$K:$L, 2, FALSE), "") | Y30: =IFERROR(AVERAGE(U30:X30),"")
B31: =IFERROR(VLOOKUP(C31,'초지 품명..'!$I:$J,2,FALSE), "") | L31: =IFERROR(VLOOKUP(M31, '초지 품명..'!$P:$Q, 2, FALSE), "") | N31: =IFERROR(VLOOKUP(O31, '초지 품명..'!$K:$L, 2, FALSE), "") | Y31: =IFERROR(AVERAGE(U31:X31),"")
B32: =IFERROR(VLOOKUP(C32,'초지 품명..'!$I:$J,2,FALSE), "") | L32: =IFERROR(VLOOKUP(M32, '초지 품명..'!$P:$Q, 2, FALSE), "") | N32: =IFERROR(VLOOKUP(O32, '초지 품명..'!$K:$L, 2, FALSE), "") | Y32: =IFERROR(AVERAGE(U32:X32),"")
B33: =IFERROR(VLOOKUP(C33,'초지 품명..'!$I:$J,2,FALSE), "") | L33: =IFERROR(VLOOKUP(M33, '초지 품명..'!$P:$Q, 2, FALSE), "") | N33: =IFERROR(VLOOKUP(O33, '초지 품명..'!$K:$L, 2, FALSE), "") | Y33: =IFERROR(AVERAGE(U33:X33),"")
B34: =IFERROR(VLOOKUP(C34,'초지 품명..'!$I:$J,2,FALSE), "") | L34: =IFERROR(VLOOKUP(M34, '초지 품명..'!$P:$Q, 2, FALSE), "") | N34: =IFERROR(VLOOKUP(O34, '초지 품명..'!$K:$L, 2, FALSE), "") | Y34: =IFERROR(AVERAGE(U34:X34),"")
B35: =IFERROR(VLOOKUP(C35,'초지 품명..'!$I:$J,2,FALSE), "") | L35: =IFERROR(VLOOKUP(M35, '초지 품명..'!$P:$Q, 2, FALSE), "") | N35: =IFERROR(VLOOKUP(O35, '초지 품명..'!$K:$L, 2, FALSE), "") | Y35: =IFERROR(AVERAGE(U35:X35),"")
B36: =IFERROR(VLOOKUP(C36,'초지 품명..'!$I:$J,2,FALSE), "") | L36: =IFERROR(VLOOKUP(M36, '초지 품명..'!$P:$Q, 2, FALSE), "") | N36: =IFERROR(VLOOKUP(O36, '초지 품명..'!$K:$L, 2, FALSE), "") | Y36: =IFERROR(AVERAGE(U36:X36),"")
B37: =IFERROR(VLOOKUP(C37,'초지 품명..'!$I:$J,2,FALSE), "") | L37: =IFERROR(VLOOKUP(M37, '초지 품명..'!$P:$Q, 2, FALSE), "") | N37: =IFERROR(VLOOKUP(O37, '초지 품명..'!$K:$L, 2, FALSE), "") | Y37: =IFERROR(AVERAGE(U37:X37),"")
... B57: =IFERROR(VLOOKUP(C57,'초지 품명..'!$I:$J,2,FALSE), "") | L57: =IFERROR(VLOOKUP(M57, '초지 품명..'!$P:$Q, 2, FALSE), "") | N57: =IFERROR(VLOOKUP(O57, '초지 품명..'!$K:$L, 2, FALSE), "") | Y57: =IFERROR(AVERAGE(U57:X57),"")
B58: =IFERROR(VLOOKUP(C58,'초지 품명..'!$I:$J,2,FALSE), "") | L58: =IFERROR(VLOOKUP(M58, '초지 품명..'!$P:$Q, 2, FALSE), "") | Y58: =IFERROR(AVERAGE(U58:X58),"")
B59: =IFERROR(VLOOKUP(C59,'초지 품명..'!$I:$J,2,FALSE), "") | L59: =IFERROR(VLOOKUP(M59, '초지 품명..'!$P:$Q, 2, FALSE), "") | Y59: =IFERROR(AVERAGE(U59:X59),"")
...

Sheet 초지 품명..
A1: 초지 | I1: 생산 호기 | J1: 설비코드 | K1: 적용 호기 | L1: 설비코드 | M1: 월 | N1: 성명 | O1: 기준 | P1: 품명 | Q1: 자재코드
B2: 기준 | C2: 품명 | I2: 초지3 | J2: TAA03 | K2: 가공2 | L2: TRA02 | M2: 01월 | N2: 송지숙 | O2: 14.8 | P2: 데코 (일반) 3P | Q2: HRT-Z110006
A3: 가공용 | B3: 13.3 | C3: 미용 소프티 | D3: 1375 | I3: 초지4 | J3: TAA04 | K3: 가공3 | L3: TRA03 | M3: 02월 | N3: 박용주 | O3: 14.8 | P3: 데코 (일반) 3P (코튼) | Q3: HRT-Z110007
B4: 13.8 | C4: 데코 (기획) 3P | D4: 2930 | E4: 초 3,4 | F4: 가공4 | I4: 초지5 | J4: TAA05 | K4: 가공3 (창고용) | M4: 03월 | N4: 권혜림 | O4: 14.3 | P4: 데코 (기획) 3P | Q4: HRT-Z010002
D5: 2950 | F5: 가공3,5 | K5: 가공4 | L5: TRA04 | M5: 04월 | N5: 문종실 | O5: 14.8 | P5: 시그니처 3P | Q5: HRT-Z140003
C6: 시그니처 | D6: 2950 | K6: 가공5 | L6: TRA05 | M6: 05월 | O6: 14.3 | P6: 4겹 데코 | Q6: HRT-Z150006M
C7: 4겹 데코 | D7: 2950 | K7: 가공5 22m용 | M7: 06월 | O7: 14.8 | P7: 4겹 데코 (코튼) | Q7: HRT-Z030023M
B8: 14 | C8: 데코 (기획) 3P | D8: 2930 | E8: 초5 | F8: 가공4 | K8: 가공6 | L8: TRA06 | M8: 07월 | O8: 21.5 | P8: 미용 소프티 | Q8: HRT-Z030021M
D9: 2950 | F9: 가공3,5 | K9: 가공6 (창고용) | M9: 08월 | O9: 19.5 | P9: K/T (2겹) | Q9: HRT-Z030005
C10: 시그니처 3P | D10: 2950 | K10: 정비 운휴 | M10: 09월 | O10: 16.8 | P10: K/T (3겹) | Q10: HRT-Z030004
C11: 4겹 데코 | D11: 2950 | K11: 급전 운휴 | M11: 10월 | O11: 16.8 | P11: 촉앤감 3P | Q11: HRT-Z030003
B12: 14.8 | C12: 촉앤감 미용 | D12: 1375 | K12: Felt 세척 운휴 | M12: 11월 | O12: 14.3 | P12: 촉앤감 미용 | Q12: HRT-Z030004
B13: 14.8 | C13: 고지 (일반) 3P | D13: 2950 | K13: 초출 준비 | M13: 12월 | O13: 15.8 | P13: 고지 (일반) 3P | Q13: HRT-Z110007
B14: 14.8 | C14: 데코 (일반) 3P | D14: 2930 | E14: 초 3,4 | F14: 가공4 | K14: 계획 운휴 | O14: 15.8 | P14: 깨/나 (일반) 2P | Q14: HRT-Z130003
D15: 2950 | F15: 가공3,5 | K15: 폐기 | P15: 데코 (일반) 2P | Q15: HRT-Z140003
B16: 14.8 | C16: PCMC 3P (일반) | D16: 2930 | E16: 초4 | K16: 명절 운휴 | O16: 14.3 | P16: 대한 2J 15.5 | Q16: HRT-Z150006M
B17: 15 | C17: 데코 (일반) 3P | D17: 2930 | E17: 초5 | K17: 편제 운휴 | O17: 14.8 | P17: PCMC 3P (기획) | Q17: HRT-Z030023M
D18: 2950 | K18: 재고 조정 운휴 | O18: 18 | P18: PCMC 3P (일반) | Q18: HRT-Z030021M
B19: 15 | C19: 3겹 (비데케어) | D19: 2950 | K19: 판매용 | P19: PCMC 3P (고평량) | Q19: HRT-Z030005
B20: 15.8 | C20: 깨/나 (일반) 2P | D20: 2930 | K20: 가공5 (창고용) | P20: 디케이(3겹) 14.0 | Q20: HRT-Z030004
B21: 15.8 | C21: 데코 (일반) 2P | D21: 2930 | E21: 초3,4,5 동일 | K21: 가공4 (창고용) | P21: I.T.C 14.2g | Q21: HRT-Z030003
B22: 16.8 | C22: 촉앤감(코튼) | D22: 2950 | E22: 초5 | K22: 가공4 (수출용) | P22: 대한 R15.0 | Q22: HRT-Z110006
B23: 16.8 | C23: 촉앤감 (고평량) | D23: 2950 | E23: 초5 | K23: 하기휴가 운휴 | P23: I.T.C R15.0 3P | Q23: HRT-Z110007
B24: 17.5 | C24: PCMC 3P (고평량) | D24: 2950 | E24: 초4 | K24: 정전 운휴 | P24: 비데케어 | Q24: HRT-Z130003
B25: 21.5 | C25: K/T (2겹) | D25: 2960 | P25: 동림 R 15.5 | Q25: HRT-Z140003
B26: 19.5 | C26: K/T (3겹) | D26: 2960 | P26: 포밍티슈 15.5 | Q26: HRT-Z150006M
A27: 판매용 | B27: 14 | C27: 디케이 (3겹) | D27: 1380 | E27: 펄프 | P27: I.T.C R15.5 2P | Q27: HRT-Z030023M
B28: 14.3 | C28: I.T.C 14.3g | D28: 2800 | E28: 펄프 | P28: 나라손 R15.8 2P | Q28: HRT-Z030021M
B29: 15 | C29: 대한 R15.0 | D29: 2800 | P29: 3R 19.0 | Q29: HRT-Z030005
B30: 15 | C30: I.T.C R15.0 3P | D30: 2800 | E30: 펄프 | P30: 와딩 1P 20.0 | Q30: HRT-Z030004
B31: 15.5 | C31: 대한 2J 15.5 | D31: 1380 | P31: 동방 1J 20.0 | Q31: HRT-Z030003
B32: 15.5 | C32: 동림 R 15.5 | D32: 1470 | P32: 대한 1J 21.0 | Q32: HRT-Z110006
B33: 15.5 | C33: 포밍티슈 | D33: 1400 | P33: 일원 H/T 21.0 | Q33: HRT-Z110007
B34: 15.5 | C34: I.T.C R15.5 2P | D34: 1415 | E34: 고지 | P34: 쌍기 K/T 21.0 | Q34: HRT-Z130003
B35: 15.8 | C35: 나라손 R15.8 2P | D35: 2820 | P35: 대한 1J 22.0 | Q35: HRT-Z140003
B36: 19 | C36: 3R | D36: 943 | P36: 깨/나 (일반) 3P | Q36: HRT-Z150006M
B37: 20 | C37: 와딩1P | D37: 1400 | O37: 15.1 | P37: FT 3겹 쉬폰 원단 | Q37: HRT-Z030023M
B38: 20 | C38: 동방 1J 20.0 | D38: 2880 | P38: 이루모스 1J 19.5 | Q38: HRT-Z030021M
B39: 20 | C39: 유송 K/T | D39: 1400 | P39: 이루모스 2J 14.5 | Q39: HRT-Z030005
B40: 21 | C40: 대한 1J 21.0 | D40: 1380 | P40: 이루모스 K/T 19.0 | Q40: HRT-Z030004
...

Sheet 가공3.4.5.6(QLT05)
C2: [ 2026년 1월~12월 검사결과 ]
B3: 호기코드 | C3: 호기 | D3: 날짜 | E3: 검사자 | G3: 19 | I3: 기준 평량 | J3: 기준 길이/매수 | K3: 원지 로트번호 | L3: 품목 | M3: 지종 | N3: 구분 | O3: 자재코드 | P3: 품명 | Q3: 겹수 | R3: 롤 | S3: 외관검수 | T3: 지 폭 (mm) | U3: 절취간격 | V3: 직 경 (mm) | W3: 타이트 | X3: 타이트 | Y3: 길 이(m) / 매수 | Z3: 평량 | AA3: 파 강 | AB3: 절취강도 | AC3: 두께 | AH3: 두께 평균 | AI3: 테일강도 | AK3: 절취선 상태 | AL3: 테일 겹분리 | AM3: 이물질 혼입 | AN3: 엠보싱 상태 | AO3: 포장 상태 | AP3: 냄 새 | AQ3: 형광검출 유/무 | AR3: 판 정 | AS3: 비고
E4: 성 명 | F4: 반 | G4: 시 | H4: 분 | U4: (mm) | W4: 니스 | Z4: (g/㎡) | AA4: (mN) | AB4: (gf/mm) | AC4: 1 | AD4: 2 | AE4: 3 | AF4: 4 | AG4: 5 | AI4: 강도 | AJ4: 길이
B5: MACH_CD | C5: MACH_NM | D5: MSRM_DATE | E5: MSRM_NM | F5: WRK_CLASS | G5: TIME_HOUR | H5: TIME_MIN | K5: LOT_NO | O5: MATNR | P5: MATNR_NM | Q5: LAYER_CNT | R5: ROLL_CNT | T5: WIDTH | U5: CUT_INT | V5: DIAM | W5: RED_DIAM | X5: RED_RATE | Y5: LEN_CNT | Z5: BS_WGT | AA5: BREAK | AB5: CUT_STR | AH5: THK_AVG | AI5: TAIL_STR | AJ5: LENGTH | AK5: CUT_LINE | AL5: TAIL_SPLT | AM5: CONTAM | AN5: EMBOSS | AO5: PACK_STS | AP5: SMELL | AQ5: FLUORO | AR5: FNL_JDGM | AS5: RMK
A6: 월별 | C6: 가공6 | D6: 7월 2일 | E6: 송지숙 | F6: 2 | G6: 3 | H6: 50 | K6: 180630E113 | L6: RT | N6: 일반/기획 | P6: 촉&감 3겹데코 디럭스 30m (블루) | Q6: 3 | R6: 30 | S6: 적 합 | T6: 107 | V6: 124 | Y6: 30.6 | Z6: 15 | AA6: 2941 | AB6: 1070 | AI6: 140↓ | AK6: 양호 | AL6: 합격 | AM6: 무 | AN6: 양호 | AO6: 양호 | AP6: 벚꽃향 | AR6: 합격
A7: 1월 | C7: 가공3 | D7: 46023 | E7: 박용주 | F7: 4 | G7: 8 | H7: 30 | I7: 20 | J7: 140 | K7: 251222C017 | L7: K/T | P7: 데일리 아껴쓰는 키친타올 140매 | Q7: 2 | R7: 8 | S7: 적 합 | T7: 192 | U7: 121 | V7: 125 | W7: 116 | X7: =IFERROR((V7-W7)/V7*100,"") -> 7.2 | Y7: 140 | Z7: 20.01 | AA7: 3869 | AB7: 1370 | AC7: 0.644 | AD7: 0.592 | AE7: 0.639 | AF7: 0.634 | AG7: 0.642 | AH7: =IFERROR(AVERAGE(AC7:AG7),"") -> 0.6302 | AK7: 양호 | AL7: 합격 | AM7: 무 | AN7: 양호 | AO7: 양호 | AP7: 무 | AQ7: 불검출 | AR7: 합격
A8: 1월 | C8: 가공6 | D8: 46023 | E8: 박용주 | F8: 4 | G8: 8 | H8: 50 | I8: 14.5 | J8: 30 | K8: 포장기고장 | L8: R/T | N8: 일반 | P8: 3겹 순수 프리미엄 (더 클래스) 30m | Q8: 3 | R8: 30 | T8: 98 | U8: 114 | V8: 125 | W8: 121 | X8: =IFERROR((V8-W8)/V8*100,"") -> 3.2 | Y8: 30.2 | Z8: 14.71 | AA8: 2777 | AB8: 1100 | AC8: 0.42 | AD8: 0.409 | AE8: 0.445 | AF8: 0.431 | AG8: 0.421 | AH8: =IFERROR(AVERAGE(AC8:AG8),"") -> 0.4252
A9: 1월 | C9: 가공4 | D9: 46023 | E9: 박용주 | F9: 4 | G9: 9 | H9: 30 | I9: 14 | J9: 30 | K9: 251231B025 | L9: R/T | M9: 고지 | N9: 일반 | P9: 깨끗한나라 데코 앤 라벤더 30m | Q9: 3 | R9: 30 | S9: 적 합 | T9: 97 | U9: 113 | V9: 121 | W9: 118 | X9: =IFERROR((V9-W9)/V9*100,"") -> 2.4793388 | Y9: 30.6 | Z9: 14.61 | AA9: 2658 | AB9: 1110 | AC9: 0.487 | AD9: 0.537 | AE9: 0.499 | AF9: 0.49 | AG9: 0.494 | AH9: =IFERROR(AVERAGE(AC9:AG9),"") -> 0.5014 | AK9: 양호 | AL9: 합격 | AM9: 무 | AN9: 양호 | AO9: 양호 | AP9: 라벤더향 | AR9: 합격
A10: 1월 | C10: 가공5 | D10: 46023 | E10: 박용주 | F10: 4 | G10: 9 | H10: 50 | I10: 13.5 | J10: 22 | K10: 251230C012 | L10: R/T | N10: 기획 | P10: 3겹 니가 필요해 22m | Q10: 3 | R10: 30 | S10: 적 합 | T10: 96 | U10: 113 | V10: 111 | W10: 103 | X10: =IFERROR((V10-W10)/V10*100,"") -> 7.2072072 | Y10: 22.5 | Z10: 13.43 | AA10: 3325 | AB10: 1040 | AC10: 0.39 | AD10: 0.381 | AE10: 0.39 | AF10: 0.422 | AG10: 0.377 | AH10: =IFERROR(AVERAGE(AC10:AG10),"") -> 0.392 | AK10: 양호 | AL10: 합격 | AM10: 무 | AN10: 양호 | AO10: 양호 | AP10: 무 | AQ10: 불검출 | AR10: 합격
A11: 1월 | C11: 가공3 | D11: 46023 | E11: 박용주 | F11: 4 | G11: 12 | H11: 0 | I11: 20 | J11: 140 | K11: 무인지게차 오류 | L11: K/T | P11: 데일리 아껴쓰는 키친타올 140매 | Q11: 2 | R11: 8 | T11: 192 | U11: 120 | V11: 125 | Y11: 140 | Z11: 19.74 | AA11: 3995 | AB11: 1190
A12: 1월 | C12: 가공6 | D12: 46023 | E12: 박용주 | F12: 4 | G12: 12 | H12: 30 | I12: 14.5 | J12: 30 | K12: 무인지게차 오류 | L12: R/T | N12: 일반 | P12: 3겹 순수 프리미엄 (더 클래스) 30m | Q12: 3 | R12: 30 | T12: 98 | U12: 114 | V12: 126 | Y12: 30.1 | Z12: 14.18 | AA12: 2690 | AB12: 1280
A13: 1월 | C13: 가공4 | D13: 46023 | E13: 박용주 | F13: 4 | G13: 13 | H13: 0 | I13: 14 | J13: 30 | K13: 251231B016 | L13: R/T | M13: 고지 | N13: 일반 | P13: 깨끗한나라 데코 앤 라벤더 30m | Q13: 3 | R13: 30 | S13: 적 합 | T13: 97 | U13: 113 | V13: 122 | Y13: 30.6 | Z13: 14.39 | AA13: 2938 | AB13: 1260 | AK13: 양호 | AL13: 합격 | AM13: 무 | AN13: 양호 | AO13: 양호 | AP13: 라벤더향 | AR13: 합격
A14: 1월 | C14: 가공5 | D14: 46023 | E14: 박용주 | F14: 4 | G14: 13 | H14: 20 | I14: 13.5 | J14: 22 | K14: 251230C005 | L14: R/T | N14: 기획 | P14: 3겹 니가 필요해 22m | Q14: 3 | R14: 30 | S14: 적 합 | T14: 96 | U14: 113 | V14: 111 | Y14: 22.4 | Z14: 13.79 | AA14: 3985 | AB14: 1090 | AK14: 양호 | AL14: 합격 | AM14: 무 | AN14: 양호 | AO14: 양호 | AP14: 무 | AQ14: 불검출 | AR14: 합격
A15: 1월 | C15: 가공6 | D15: 46023 | E15: 문종실 | F15: 3 | G15: 15 | H15: 50 | I15: 14.5 | J15: 30 | K15: 251231D024 | L15: R/T | N15: 일반 | P15: 3겹 순수 프리미엄 (더 클래스) 30m | Q15: 3 | R15: 30 | S15: 적 합 | T15: 98 | U15: 114 | V15: 126 | W15: 122 | X15: =IFERROR((V15-W15)/V15*100,"") -> 3.1746032 | Y15: 30.1 | Z15: 14.41 | AA15: 3341 | AB15: 1110 | AC15: 0.442 | AD15: 0.432 | AE15: 0.431 | AF15: 0.424 | AG15: 0.416 | AH15: =IFERROR(AVERAGE(AC15:AG15),"") -> 0.429 | AK15: 양호 | AL15: 합격 | AM15: 무 | AN15: 양호 | AO15: 양호 | AP15: 무 | AQ15: 불검출 | AR15: 합격
A16: 1월 | C16: 가공3 | D16: 46023 | E16: 문종실 | F16: 3 | G16: 16 | H16: 10 | I16: 20 | J16: 140 | K16: 251222C015 | L16: K/T | P16: 데일리 아껴쓰는 키친타올 140매 | Q16: 2 | R16: 8 | S16: 적 합 | T16: 193 | U16: 121 | V16: 125 | W16: 117 | X16: =IFERROR((V16-W16)/V16*100,"") -> 6.4 | Y16: 140 | Z16: 20.21 | AA16: 4507 | AB16: 710 | AC16: 0.679 | AD16: 0.643 | AE16: 0.692 | AF16: 0.683 | AG16: 0.651 | AH16: =IFERROR(AVERAGE(AC16:AG16),"") -> 0.6696 | AK16: 양호 | AL16: 합격 | AM16: 무 | AN16: 양호 | AO16: 양호 | AP16: 무 | AQ16: 불검출 | AR16: 합격
A17: 1월 | C17: 가공4 | D17: 46023 | E17: 문종실 | F17: 3 | G17: 16 | H17: 50 | I17: 14 | J17: 30 | K17: 251231B018 | L17: R/T | M17: 고지 | N17: 일반 | P17: 깨끗한나라 데코 앤 라벤더 30m | Q17: 3 | R17: 30 | S17: 적 합 | T17: 97 | U17: 113 | V17: 121 | W17: 118 | X17: =IFERROR((V17-W17)/V17*100,"") -> 2.4793388 | Y17: 30.6 | Z17: 14.34 | AA17: 3056 | AB17: 1200 | AC17: 0.52 | AD17: 0.501 | AE17: 0.508 | AF17: 0.481 | AG17: 0.489 | AH17: =IFERROR(AVERAGE(AC17:AG17),"") -> 0.4998 | AK17: 양호 | AL17: 합격 | AM17: 무 | AN17: 양호 | AO17: 양호 | AP17: 라벤더향 | AR17: 합격
A18: 1월 | C18: 가공5 | D18: 46023 | E18: 문종실 | F18: 3 | G18: 17 | H18: 20 | I18: 13.5 | J18: 22 | K18: 251230C017 | L18: R/T | N18: 기획 | P18: 3겹 니가 필요해 22m | Q18: 3 | R18: 30 | S18: 적 합 | T18: 96 | U18: 113 | V18: 111 | W18: 105 | X18: =IFERROR((V18-W18)/V18*100,"") -> 5.4054054 | Y18: 22.3 | Z18: 13.06 | AA18: 2776 | AB18: 820 | AC18: 0.391 | AD18: 0.435 | AE18: 0.411 | AF18: 0.435 | AG18: 0.391 | AH18: =IFERROR(AVERAGE(AC18:AG18),"") -> 0.4126 | AK18: 양호 | AL18: 불합격 | AM18: 무 | AN18: 양호 | AO18: 양호 | AP18: 무 | AQ18: 불검출 | AR18: 합격
A19: 1월 | C19: 가공3 | D19: 46023 | E19: 문종실 | F19: 3 | G19: 19 | H19: 40 | I19: 20 | J19: 140 | K19: 251222C008 | L19: K/T | P19: 데일리 아껴쓰는 키친타올 140매 | Q19: 2 | R19: 8 | S19: 적 합 | T19: 192 | U19: 121 | V19: 125 | Y19: 140 | Z19: 20.25 | AA19: 4904 | AB19: 1700 | AK19: 양호 | AL19: 합격 | AM19: 무 | AN19: 양호 | AO19: 양호 | AP19: 무 | AQ19: 불검출 | AR19: 합격
A20: 1월 | C20: 가공5 | D20: 46023 | E20: 문종실 | F20: 3 | G20: 21 | H20: 0 | I20: 13.5 | J20: 22 | K20: 251230C014 | L20: R/T | N20: 기획 | P20: 3겹 니가 필요해 22m | Q20: 3 | R20: 30 | S20: 적 합 | T20: 96 | U20: 113 | V20: 111 | Y20: 22.3 | Z20: 13.64 | AA20: 3052 | AB20: 1120 | AI20: 30 | AJ20: 0.6 | AK20: 양호 | AL20: 불합격 | AM20: 무 | AN20: 양호 | AO20: 양호 | AP20: 무 | AQ20: 불검출 | AR20: 합격
A21: 1월 | C21: 가공4 | D21: 46023 | E21: 문종실 | F21: 3 | G21: 21 | H21: 20 | I21: 14 | J21: 30 | K21: 251231B009 | L21: R/T | M21: 고지 | N21: 일반 | P21: 깨끗한나라 데코 앤 라벤더 30m | Q21: 3 | R21: 30 | S21: 적 합 | T21: 97 | U21: 114 | V21: 122 | Y21: 30.5 | Z21: 14.46 | AA21: 3216 | AB21: 1070 | AI21: 100 | AJ21: 1.6 | AK21: 양호 | AL21: 합격 | AM21: 무 | AN21: 양호 | AO21: 양호 | AP21: 라벤더향 | AR21: 합격
A22: 1월 | C22: 가공6 | D22: 46023 | E22: 문종실 | F22: 3 | G22: 21 | H22: 40 | I22: 14.5 | J22: 27 | K22: 260101D015 | L22: R/T | N22: 일반 | P22: 3겹 순수 프리미엄 27m (P) | Q22: 3 | R22: 30 | S22: 적 합 | T22: 107 | U22: 114 | V22: 120 | Y22: 27.3 | Z22: 14.51 | AA22: 2719 | AB22: 1280 | AI22: 90 | AJ22: 0.5 | AK22: 양호 | AL22: 합격 | AM22: 무 | AN22: 양호 | AO22: 양호 | AP22: 무 | AQ22: 불검출 | AR22: 합격
A23: 1월 | C23: 가공6 | D23: 46023 | E23: 권혜림 | F23: 1 | G23: 23 | H23: 50 | I23: 14.5 | J23: 27 | K23: 260101D012 | L23: R/T | N23: 일반 | P23: 3겹 순수 프리미엄 27m (P) | Q23: 3 | R23: 30 | S23: 적 합 | T23: 107 | U23: 113 | V23: 119 | W23: 116 | X23: =IFERROR((V23-W23)/V23*100,"") -> 2.5210084 | Y23: 27.2 | Z23: 14.21 | AA23: 3396 | AB23: 1370 | AC23: 0.423 | AD23: 0.414 | AE23: 0.431 | AF23: 0.437 | AG23: 0.449 | AH23: =IFERROR(AVERAGE(AC23:AG23),"") -> 0.4308 | AK23: 양호 | AL23: 합격 | AM23: 무 | AN23: 양호 | AO23: 양호 | AP23: 무 | AQ23: 불검출 | AR23: 합격
A24: 1월 | C24: 가공3 | D24: 46023 | E24: 권혜림 | F24: 1 | G24: 24 | H24: 10 | I24: 20 | J24: 140 | K24: 251222C002 | L24: K/T | P24: 데일리 아껴쓰는 키친타올 140매 | Q24: 2 | R24: 8 | S24: 적 합 | T24: 192 | U24: 120 | V24: 124 | W24: 117 | X24: =IFERROR((V24-W24)/V24*100,"") -> 5.6451613 | Y24: 140 | Z24: 20.4 | AA24: 3679 | AB24: 1360 | AC24: 0.648 | AD24: 0.647 | AE24: 0.666 | AF24: 0.629 | AG24: 0.591 | AH24: =IFERROR(AVERAGE(AC24:AG24),"") -> 0.6362 | AK24: 양호 | AL24: 합격 | AM24: 무 | AN24: 양호 | AO24: 양호 | AP24: 무 | AQ24: 불검출 | AR24: 합격
A25: 1월 | C25: 가공4 | D25: 46023 | E25: 권혜림 | F25: 1 | G25: 1 | H25: 10 | I25: 14 | J25: 30 | K25: 251231B002 | L25: R/T | M25: 고지 | N25: 일반 | P25: 깨끗한나라 데코 앤 라벤더 30m | Q25: 3 | R25: 30 | S25: 적 합 | T25: 97 | U25: 113 | V25: 122 | W25: 119 | X25: =IFERROR((V25-W25)/V25*100,"") -> 2.4590164 | Y25: 30.7 | Z25: 14.52 | AA25: 2551 | AB25: 1340 | AC25: 0.514 | AD25: 0.522 | AE25: 0.498 | AF25: 0.521 | AG25: 0.521 | AH25: =IFERROR(AVERAGE(AC25:AG25),"") -> 0.5152 | AK25: 양호 | AL25: 합격 | AM25: 무 | AN25: 양호 | AO25: 양호 | AP25: 라벤더향 | AR25: 합격
A26: 1월 | C26: 가공5 | D26: 46023 | E26: 권혜림 | F26: 1 | G26: 1 | H26: 30 | I26: 13.5 | J26: 30 | K26: 251230C007 | L26: R/T | N26: 기획 | P26: 3겹 퓨어앤데코 30m (특판납품용)(S) | Q26: 3 | R26: 30 | S26: 적 합 | T26: 96 | U26: 112 | V26: 121 | W26: 116 | X26: =IFERROR((V26-W26)/V26*100,"") -> 4.1322314 | Y26: 30.3 | Z26: 13.6 | AA26: 3012 | AB26: 1150 | AC26: 0.383 | AD26: 0.426 | AE26: 0.376 | AF26: 0.361 | AG26: 0.368 | AH26: =IFERROR(AVERAGE(AC26:AG26),"") -> 0.3828 | AK26: 양호 | AL26: 불합격 | AM26: 무 | AN26: 양호 | AO26: 양호 | AP26: 무 | AQ26: 불검출 | AR26: 합격
A27: 1월 | C27: 가공6 | D27: 46023 | E27: 권혜림 | F27: 1 | K27: 무인지게차 오류
A28: 1월 | C28: 가공4 | D28: 46023 | E28: 권혜림 | F28: 1 | G28: 4 | H28: 30 | I28: 15.5 | J28: 50 | K28: 260101B022 | L28: R/T | M28: 고지 | N28: 일반 | P28: 깨끗한나라 2겹 에코베이직 50m | Q28: 2 | R28: 30 | S28: 적 합 | T28: 98 | U28: 113 | V28: 126 | Y28: 50.7 | Z28: 16.29 | AA28: 1614 | AB28: 1030 | AI28: 100 | AJ28: 1.8 | AK28: 양호 | AL28: 불합격 | AM28: 무 | AN28: 양호 | AO28: 양호 | AP28: 무 | AR28: 합격
A29: 1월 | C29: 가공5 | D29: 46023 | E29: 권혜림 | F29: 1 | G29: 4 | H29: 50 | I29: 13.5 | J29: 30 | K29: 251231C001 | L29: R/T | N29: 기획 | P29: 3겹 퓨어앤데코 30m (특판납품용)(S) | Q29: 3 | R29: 30 | S29: 지관 찢어짐 불량 | T29: 96 | U29: 113 | V29: 121 | Y29: 30.3 | Z29: 13.23 | AA29: 3837 | AB29: 1080 | AI29: 50 | AJ29: 0.8 | AK29: 양호 | AL29: 불합격 | AM29: 무 | AN29: 양호 | AO29: 양호 | AP29: 무 | AQ29: 불검출 | AR29: 불합격
A30: 1월 | C30: 가공3 | D30: 46023 | E30: 권혜림 | F30: 1 | G30: 5 | H30: 50 | I30: 20 | J30: 100 | K30: 251222C004 | L30: K/T | P30: 명절 요리 준비 싹쓸이 키친타월 100매 | Q30: 2 | R30: 6 | S30: 적 합 | T30: 222 | U30: 121 | V30: 109 | Y30: 100 | Z30: 19.92 | AA30: 4689 | AB30: 1720 | AK30: 양호 | AL30: 합격 | AM30: 무 | AN30: 양호 | AO30: 양호 | AP30: 무 | AQ30: 불검출 | AR30: 합격 | AS30: 신제품
A31: 1월 | C31: 가공6 | D31: 46023 | E31: 권혜림 | F31: 1 | G31: 6 | H31: 30 | I31: 14.5 | J31: 27 | K31: 외관검수 | L31: R/T | N31: 일반 | P31: 3겹 순수 프리미엄 27m (P) | Q31: 3 | R31: 30 | T31: 107 | U31: 114 | V31: 119 | Y31: 27.2 | Z31: 14.22 | AA31: 4040 | AB31: 1420
A32: 1월 | C32: 가공3 | D32: 46024 | E32: 박용주 | F32: 4 | G32: 8 | H32: 50 | I32: 20 | J32: 100 | K32: 251222C004 | L32: K/T | P32: 명절 요리 준비 싹쓸이 키친타월 100매 | Q32: 2 | R32: 6 | S32: 적 합 | T32: 222 | U32: 121 | V32: 109 | W32: 102 | X32: =IFERROR((V32-W32)/V32*100,"") -> 6.4220183 | Y32: 100 | Z32: 20.37 | AA32: 4669 | AB32: 1680 | AC32: 0.735 | AD32: 0.675 | AE32: 0.673 | AF32: 0.696 | AG32: 0.709 | AH32: =IFERROR(AVERAGE(AC32:AG32),"") -> 0.6976 | AK32: 양호 | AL32: 합격 | AM32: 무 | AN32: 양호 | AO32: 양호 | AP32: 무 | AQ32: 불검출 | AR32: 합격
A33: 1월 | C33: 가공6 | D33: 46024 | E33: 박용주 | F33: 4 | G33: 8 | H33: 20 | I33: 14.5 | J33: 27 | K33: 무인지게차 오류 | L33: R/T | N33: 일반 | P33: 3겹 순수 프리미엄 27m (P) | Q33: 3 | R33: 30 | T33: 106 | U33: 113 | V33: 119 | W33: 116 | X33: =IFERROR((V33-W33)/V33*100,"") -> 2.5210084 | Y33: 27.2 | Z33: 14.4 | AA33: 3279 | AB33: 1430 | AC33: 0.397 | AD33: 0.385 | AE33: 0.393 | AF33: 0.399 | AG33: 0.413 | AH33: =IFERROR(AVERAGE(AC33:AG33),"") -> 0.3974
A34: 1월 | C34: 가공4 | D34: 46024 | E34: 박용주 | F34: 4 | G34: 9 | H34: 50 | I34: 15.5 | J34: 50 | K34: 260101B031 | L34: R/T | M34: 고지 | N34: 일반 | P34: 깨끗한나라 2겹 에코베이직 50m | Q34: 2 | R34: 30 | S34: 텐실부위 절취불량 | T34: 97 | U34: 114 | V34: 127 | W34: 124 | X34: =IFERROR((V34-W34)/V34*100,"") -> 2.3622047 | Y34: 51 | Z34: 16.36 | AA34: 2277 | AB34: 940 | AC34: 0.345 | AD34: 0.344 | AE34: 0.366 | AF34: 0.346 | AG34: 0.36 | AH34: =IFERROR(AVERAGE(AC34:AG34),"") -> 0.3522 | AK34: 불량 | AL34: 불합격 | AM34: 무 | AN34: 양호 | AO34: 양호 | AP34: 무 | AR34: 불합격
A35: 1월 | C35: 가공5 | D35: 46024 | E35: 박용주 | F35: 4 | G35: 10 | H35: 10 | I35: 13.5 | J35: 30 | K35: 251229C017 | L35: R/T | N35: 기획 | P35: 3겹 퓨어앤데코 30m (특판납품용)(S) | Q35: 3 | R35: 30 | S35: 적 합 | T35: 96 | U35: 112 | V35: 121 | W35: 114 | X35: =IFERROR((V35-W35)/V35*100,"") -> 5.785124 | Y35: 30.3 | Z35: 13.37 | AA35: 2772 | AB35: 1000 | AC35: 0.38 | AD35: 0.392 | AE35: 0.379 | AF35: 0.424 | AG35: 0.397 | AH35: =IFERROR(AVERAGE(AC35:AG35),"") -> 0.3944 | AK35: 양호 | AL35: 불합격 | AM35: 무 | AN35: 양호 | AO35: 양호 | AP35: 무 | AQ35: 불검출 | AR35: 합격
A36: 1월 | C36: 가공3 | D36: 46024 | E36: 박용주 | F36: 4 | G36: 12 | H36: 30 | I36: 20 | J36: 100 | K36: 251221C029 | L36: K/T | P36: 명절 요리 준비 싹쓸이 키친타월 100매 | Q36: 2 | R36: 6 | S36: 적 합 | T36: 221 | U36: 121 | V36: 109 | Y36: 100 | Z36: 20.27 | AA36: 4229 | AB36: 1360 | AK36: 양호 | AL36: 합격 | AM36: 무 | AN36: 양호 | AO36: 양호 | AP36: 무 | AQ36: 불검출 | AR36: 합격
A37: 1월 | C37: 가공6 | D37: 46024 | E37: 박용주 | F37: 4 | G37: 12 | H37: 10 | I37: 14.5 | J37: 27 | K37: 260101D026 | L37: R/T | N37: 일반 | P37: 3겹 순수 프리미엄 27m (P) | Q37: 3 | R37: 30 | S37: 적 합 | T37: 106 | U37: 114 | V37: 120 | Y37: 27.2 | Z37: 14.41 | AA37: 3857 | AB37: 1470 | AK37: 양호 | AL37: 합격 | AM37: 무 | AN37: 양호 | AO37: 양호 | AP37: 무 | AQ37: 불검출 | AR37: 합격
A38: 1월 | C38: 가공4 | D38: 46024 | E38: 박용주 | F38: 4 | G38: 13 | H38: 20 | I38: 15.5 | J38: 50 | K38: 260102B003 | L38: R/T | M38: 고지 | N38: 일반 | P38: 깨끗한나라 2겹 에코베이직 50m | Q38: 2 | R38: 30 | S38: 적 합 | T38: 98 | U38: 114 | V38: 127 | Y38: 51.1 | Z38: 15.93 | AA38: 2034 | AB38: 1170 | AK38: 양호 | AL38: 불합격 | AM38: 무 | AN38: 양호 | AO38: 양호 | AP38: 무 | AR38: 합격
A39: 1월 | C39: 가공5 | D39: 46024 | E39: 박용주 | F39: 4 | G39: 13 | H39: 40 | I39: 13.5 | J39: 30 | K39: 251229C019 | L39: R/T | N39: 기획 | P39: 3겹 퓨어앤데코 30m (특판납품용)(S) | Q39: 3 | R39: 30 | S39: 적 합 | T39: 96 | U39: 112 | V39: 121 | Y39: 30.3 | Z39: 13.36 | AA39: 3001 | AB39: 1030 | AK39: 양호 | AL39: 불합격 | AM39: 무 | AN39: 양호 | AO39: 양호 | AP39: 무 | AQ39: 불검출 | AR39: 합격
A40: 1월 | C40: 가공6 | D40: 46024 | E40: 문종실 | F40: 3 | G40: 15 | H40: 30 | I40: 14.5 | J40: 27 | K40: 260101D029 | L40: R/T | N40: 일반 | P40: 3겹 순수 프리미엄 27m (P) | Q40: 3 | R40: 30 | S40: 적 합 | T40: 107 | U40: 114 | V40: 120 | W40: 116 | X40: =IFERROR((V40-W40)/V40*100,"") -> 3.3333333 | Y40: 27.2 | Z40: 14.02 | AA40: 3191 | AB40: 880 | AC40: 0.435 | AD40: 0.418 | AE40: 0.431 | AF40: 0.424 | AG40: 0.425 | AH40: =IFERROR(AVERAGE(AC40:AG40),"") -> 0.4266 | AK40: 양호 | AL40: 합격 | AM40: 무 | AN40: 양호 | AO40: 양호 | AP40: 무 | AQ40: 불검출 | AR40: 합격
A41: 1월 | C41: 가공3 | D41: 46024 | E41: 문종실 | F41: 3 | G41: 16 | H41: 0 | I41: 20 | J41: 100 | K41: 251221C027 | L41: K/T | P41: 명절 요리 준비 싹쓸이 키친타월 100매 | Q41: 2 | R41: 6 | S41: 적 합 | T41: 223 | U41: 120 | V41: 109 | W41: 102 | X41: =IFERROR((V41-W41)/V41*100,"") -> 6.4220183 | Y41: 100 | Z41: 19.79 | AA41: 4622 | AB41: 1170 | AC41: 0.511 | AD41: 0.598 | AE41: 0.606 | AF41: 0.612 | AG41: 0.589 | AH41: =IFERROR(AVERAGE(AC41:AG41),"") -> 0.5832 | AK41: 양호 | AL41: 합격 | AM41: 무 | AN41: 양호 | AO41: 양호 | AP41: 무 | AQ41: 불검출 | AR41: 합격
...

Sheet TEST
B1: MACH_CD | C1: MACH_NM | D1: MSRM_DATE | E1: MSRM_NM | F1: WRK_CLASS | G1: TIME_HOUR | H1: TIME_MIN | K1: LOT_NO | L1: MATNR | M1: MATNR_NM | N1: MACH_CD_TRA | O1: MACH_NM_TRA | Q1: WIDTH | R1: BS_WGT | S1: WHITE | T1: BURST | Y1: MD | Z1: CD | AA1: WET_CD | AB1: ABSORB | AH1: ELONG | AI1: THICK | AJ1: WET_SOLVE | AK1: AIR_PERM | AL1: PINHOLE | AM1: SPOT | AN1: FLUORO | AO1: FNL_JDGM | AP1: RMK
K2: 12345
