Workbook

Sheet 1
B1: ◈ 원질4호기 원료처리 작업 일지 | AM1: NBKP | AO1: LBKP
B2: 1. 원료 처리 현황 | Z2: 2026 년 01 월 01 일 | AK2: 데코 | AM2: 브라츠크 | AO2: Acacia
B3: 구분 | D3: 기준 중량 (kg) | E3: 전일 재공량 | F3: 금일 재공량 | G3: 일 원료 처리량 | H3: 오전( 반) | N3: 오후( 반) | T3: 야간( 반) | Z3: 합계 | AK3: K/T | AM3: WET PULP | AO3: 수자노
H4: 데코 | N4: 데코 | T4: 데코 | Z4: 데코 | AK4: 0 | AM4: 멧자 | AO4: 아카시아APP
H5: Bale | I5: 중량 | J5: Bale | K5: 중량 | L5: Bale | M5: 중량 | N5: Bale | O5: 중량 | P5: Bale | Q5: 중량 | R5: Bale | S5: 중량 | T5: Bale | U5: 중량 | V5: Bale | W5: 중량 | X5: Bale | Y5: 중량 | Z5: 합계 | AA5: 배합비 | AB5: 합계 | AC5: 배합비 | AD5: 합계 | AE5: 배합비 | AK5: 0 | AM5: PCMC | AO5: Santafe
B6: LBKP | C6: Guaiba | D6: 247 | G6: =SUM(Z6,AB6,AD6) -> 0 | I6: =H6*D6 -> 0 | K6: =D6*J6 -> 0 | M6: =D6*L6 -> 0 | O6: =D6*N6 -> 0 | Q6: =D6*P6 -> 0 | S6: =D6*R6 -> 0 | U6: =D6*T6 -> 0 | W6: =D6*V6 -> 0 | Y6: =D6*X6 -> 0 | Z6: =SUM(I6,O6,U6) -> 0 | AA6: =IFERROR(Z10/Z16,"") -> 0.91697232 | AB6: =SUM(K6,Q6,W6) -> 0 | AC6: =IFERROR(AB10/AB16,"") | AD6: =SUM(M6,S6,Y6) -> 0 | AE6: =IFERROR(AD10/AD16,"") | AF6: 비데원지 | AM6: Pacifico | AO6: Guaiba
C7: WET(LBKP) | D7: 137 | G7: =SUM(Z7,AB7,AD7) -> 0 | I7: =H7*D7 -> 0 | K7: =D7*J7 -> 0 | M7: =D7*L7 -> 0 | O7: =D7*N7 -> 0 | Q7: =D7*P7 -> 0 | S7: =D7*R7 -> 0 | U7: =D7*T7 -> 0 | W7: =D7*V7 -> 0 | Y7: =D7*X7 -> 0 | Z7: =SUM(I7,O7,U7) -> 0 | AB7: =SUM(K7,Q7,W7) -> 0 | AD7: =SUM(M7,S7,Y7) -> 0 | AF7: 미용티슈 | AM7: Ilimsk | AO7: WET(LBKP)
C8: Acacia | D8: 250 | G8: =SUM(Z8,AB8,AD8) -> 49500 | H8: 66 | I8: =H8*D8 -> 16500 | K8: =D8*J8 -> 0 | M8: =D8*L8 -> 0 | N8: 66 | O8: =D8*N8 -> 16500 | Q8: =D8*P8 -> 0 | S8: =D8*R8 -> 0 | T8: 66 | U8: =D8*T8 -> 16500 | W8: =D8*V8 -> 0 | Y8: =D8*X8 -> 0 | Z8: =SUM(I8,O8,U8) -> 49500 | AB8: =SUM(K8,Q8,W8) -> 0 | AD8: =SUM(M8,S8,Y8) -> 0 | AF8: 3R | AM8: 크라프튼 | AO8: 0
C9: 수자노 | D9: 249 | G9: =SUM(Z9,AB9,AD9) -> 0 | I9: =H9*D9 -> 0 | K9: =D9*J9 -> 0 | M9: =D9*L9 -> 0 | O9: =D9*N9 -> 0 | Q9: =D9*P9 -> 0 | S9: =D9*R9 -> 0 | U9: =D9*T9 -> 0 | W9: =D9*V9 -> 0 | Y9: =D9*X9 -> 0 | Z9: =SUM(I9,O9,U9) -> 0 | AB9: =SUM(K9,Q9,W9) -> 0 | AD9: =SUM(M9,S9,Y9) -> 0 | AM9: 비랄 | AO9: 0
C10: 소계 | E10: =SUM(E6:E9) -> 0 | F10: =SUM(F6:F9) -> 0 | G10: =SUM(G6:G9) -> 49500 | I10: =SUM(I6:I9) -> 16500 | K10: =SUM(K6:K9) -> 0 | M10: =SUM(M6:M9) -> 0 | O10: =SUM(O6:O9) -> 16500 | Q10: =SUM(Q6:Q9) -> 0 | S10: =SUM(S6:S9) -> 0 | U10: =SUM(U6:U9) -> 16500 | W10: =SUM(W6:W9) -> 0 | Y10: =SUM(Y6:Y9) -> 0 | Z10: =SUM(Z6:Z9) -> 49500 | AB10: =SUM(AB6:AB9) -> 0 | AD10: =SUM(AD6:AD9) -> 0 | AM10: Arauco | AO10: 0
B11: NBKP | C11: 피스리버 | G11: =SUM(Z11,AB11,AD11) -> 0 | I11: =H11*D11 -> 0 | K11: =D11*J11 -> 0 | M11: =D11*L11 -> 0 | O11: =D11*N11 -> 0 | Q11: =D11*P11 -> 0 | S11: =D11*R11 -> 0 | U11: =D11*T11 -> 0 | W11: =D11*V11 -> 0 | Y11: =D11*X11 -> 0 | Z11: =SUM(I11,O11,U11) -> 0 | AA11: =IFERROR(1-AA6,"") -> 0.083027676 | AB11: =SUM(K11,Q11,W11) -> 0 | AC11: =IFERROR(1-AC6,"") | AD11: =SUM(M11,S11,Y11) -> 0 | AE11: =IFERROR(1-AE6,"") | AM11: 하우사운드
C12: Ilimsk | G12: =SUM(Z12,AB12,AD12) -> 0 | I12: =H12*D12 -> 0 | K12: =D12*J12 -> 0 | M12: =D12*L12 -> 0 | O12: =D12*N12 -> 0 | Q12: =D12*P12 -> 0 | S12: =D12*R12 -> 0 | U12: =D12*T12 -> 0 | W12: =D12*V12 -> 0 | Y12: =D12*X12 -> 0 | Z12: =SUM(I12,O12,U12) -> 0 | AB12: =SUM(K12,Q12,W12) -> 0 | AD12: =SUM(M12,S12,Y12) -> 0 | AM12: 일림
C13: 멧자 | D13: 249 | G13: =SUM(Z13,AB13,AD13) -> 4482 | H13: 6 | I13: =H13*D13 -> 1494 | K13: =D13*J13 -> 0 | M13: =D13*L13 -> 0 | N13: 6 | O13: =D13*N13 -> 1494 | Q13: =D13*P13 -> 0 | S13: =D13*R13 -> 0 | T13: 6 | U13: =D13*T13 -> 1494 | W13: =D13*V13 -> 0 | Y13: =D13*X13 -> 0 | Z13: =SUM(I13,O13,U13) -> 4482 | AB13: =SUM(K13,Q13,W13) -> 0 | AD13: =SUM(M13,S13,Y13) -> 0 | AM13: 피스리버
C14: WET PULP | D14: 150 | G14: =SUM(Z14,AB14,AD14) -> 0 | I14: =H14*D14 -> 0 | K14: =D14*J14 -> 0 | M14: =D14*L14 -> 0 | O14: =D14*N14 -> 0 | Q14: =D14*P14 -> 0 | S14: =D14*R14 -> 0 | U14: =D14*T14 -> 0 | W14: =D14*V14 -> 0 | Y14: =D14*X14 -> 0 | Z14: =SUM(I14,O14,U14) -> 0 | AB14: =SUM(K14,Q14,W14) -> 0 | AD14: =SUM(M14,S14,Y14) -> 0
C15: 소계 | E15: =SUM(E11:E14) -> 0 | F15: =SUM(F11:F14) -> 0 | G15: =SUM(G11:G14) -> 4482 | I15: =SUM(I11:I14) -> 1494 | K15: =SUM(K11:K14) -> 0 | M15: =SUM(M11:M14) -> 0 | O15: =SUM(O11:O14) -> 1494 | Q15: =SUM(Q11:Q14) -> 0 | S15: =SUM(S11:S14) -> 0 | U15: =SUM(U11:U14) -> 1494 | W15: =SUM(W11:W14) -> 0 | Y15: =SUM(Y11:Y14) -> 0 | Z15: =SUM(Z11:Z14) -> 4482 | AB15: =SUM(AB11:AB14) -> 0 | AD15: =SUM(AD11:AD14) -> 0
B16: 펄프 합계 | E16: =SUM(E15,E10) -> 0 | F16: =SUM(F15,F10) -> 0 | G16: =SUM(G10,G15) -> 53982 | H16: =SUM(H15,H10) -> 0 | I16: =SUM(I15,I10) -> 17994 | J16: =SUM(J15,J10) -> 0 | K16: =SUM(K15,K10) -> 0 | L16: =SUM(L15,L10) -> 0 | M16: =SUM(M15,M10) -> 0 | N16: =SUM(N15,N10) -> 0 | O16: =SUM(O15,O10) -> 17994 | ... Z16: =SUM(Z15,Z10) -> 53982 | AB16: =SUM(AB15,AB10) -> 0 | AD16: =SUM(AD15,AD10) -> 0
B27: 2. 원료 관리 현황
B28: 구분 | D28: 펄프 종류 | G28: N-PULP(Soft Wood) | Q28: L-PULP(Hard Wood) | AA28: 비고
D29: 브랜드 명 | G29: 피스리버 | I29: 멧자 | M29: 일림 | O29: WET PULP | S29: Guaiba | U29: 수자노 | W29: WET(LBKP) | Y29: 아카시아APP
D30: 전일 이월량 | I30: 10 | Y30: 95
B31: 오전 | D31: 입고량 | I31: 16 | Y31: 192
D32: 사용량 | I32: 6 | Y32: 66
D33: 재고량
B34: 오후 | D34: 입고량
D35: 사용량 | I35: 6 | Y35: 66
D36: 재고량
B37: 야간 | D37: 입고량
D38: 사용량 | I38: 6 | Y38: 66
D39: 재고량
B40: 펄프 합계 | D40: 총 사용량 | G40: =SUM(G32,G35,G38) -> 0 | I40: =SUM(I32,I35,I38) -> 18 | K40: =SUM(K32,K35,K38) -> 0 | M40: =SUM(M32,M35,M38) -> 0 | O40: =SUM(O32,O35,O38) -> 0 | Q40: =SUM(Q32,Q35,Q38) -> 0 | S40: =SUM(S32,S35,S38) -> 0 | U40: =SUM(U32,U35,U38) -> 0 | W40: =SUM(W32,W35,W38) -> 0 | Y40: =SUM(Y32,Y35,Y38) -> 198
D41: 총 거래 수량 | G41: =SUM(G30,G31,G34,G37) -> 0 | I41: =SUM(I30,I31,I34,I37) -> 26 | K41: =SUM(K30,K31,K34,K37) -> 0 | M41: =SUM(M30,M31,M34,M37) -> 0 | O41: =SUM(O30,O31,O34,O37) -> 0 | Q41: =SUM(Q30,Q31,Q34,Q37) -> 0 | S41: =SUM(S30,S31,S34,S37) -> 0 | U41: =SUM(U30,U31,U34,U37) -> 0 | W41: =SUM(W30,W31,W34,W37) -> 0 | Y41: =SUM(Y30,Y31,Y34,Y37) -> 287
D42: 재고량 | G42: =G41-G40 -> 0 | I42: =I41-I40 -> 8 | K42: =K41-K40 -> 0 | M42: =M41-M40 -> 0 | O42: =O41-O40 -> 0 | Q42: =Q41-Q40 -> 0 | S42: =S41-S40 -> 0 | U42: =U41-U40 -> 0 | W42: =W41-W40 -> 0 | Y42: =Y41-Y40 -> 89

Sheet 2
B1: ◈ 원질4호기 원료처리 작업 일지 | AM1: NBKP | AO1: LBKP
B2: 1. 원료 처리 현황 | Z2: 2026 년 01 월 02 일 | AK2: 데코 | AM2: 브라츠크 | AO2: Acacia
B3: 구분 | D3: 기준 중량 (kg) | E3: 전일 재공량 | F3: 금일 재공량 | G3: 일 원료 처리량 | H3: 오전( 반) | N3: 오후( 반) | T3: 야간( 반) | Z3: 합계 | AK3: K/T | AM3: WET PULP | AO3: 수자노
H4: 데코 | N4: 데코 | T4: 데코 | Z4: 데코 | AK4: 0 | AM4: 멧자 | AO4: 아카시아APP
H5: Bale | I5: 중량 | J5: Bale | K5: 중량 | L5: Bale | M5: 중량 | N5: Bale | O5: 중량 | P5: Bale | Q5: 중량 | R5: Bale | S5: 중량 | T5: Bale | U5: 중량 | V5: Bale | W5: 중량 | X5: Bale | Y5: 중량 | Z5: 합계 | AA5: 배합비 | AB5: 합계 | AC5: 배합비 | AD5: 합계 | AE5: 배합비 | AK5: 0 | AM5: PCMC | AO5: Santafe
B6: LBKP | C6: Guaiba | D6: 247 | G6: =SUM(Z6,AB6,AD6) -> 0 | I6: =H6*D6 -> 0 | K6: =D6*J6 -> 0 | M6: =D6*L6 -> 0 | O6: =D6*N6 -> 0 | Q6: =D6*P6 -> 0 | S6: =D6*R6 -> 0 | U6: =D6*T6 -> 0 | W6: =D6*V6 -> 0 | Y6: =D6*X6 -> 0 | Z6: =SUM(I6,O6,U6) -> 0 | AA6: =IFERROR(Z10/Z16,"") -> 0.91697232 | AB6: =SUM(K6,Q6,W6) -> 0 | AC6: =IFERROR(AB10/AB16,"") | AD6: =SUM(M6,S6,Y6) -> 0 | AE6: =IFERROR(AD10/AD16,"") | AF6: 비데원지 | AM6: Pacifico | AO6: Guaiba
C7: WET(LBKP) | D7: 137 | G7: =SUM(Z7,AB7,AD7) -> 0 | I7: =H7*D7 -> 0 | K7: =D7*J7 -> 0 | M7: =D7*L7 -> 0 | O7: =D7*N7 -> 0 | Q7: =D7*P7 -> 0 | S7: =D7*R7 -> 0 | U7: =D7*T7 -> 0 | W7: =D7*V7 -> 0 | Y7: =D7*X7 -> 0 | Z7: =SUM(I7,O7,U7) -> 0 | AB7: =SUM(K7,Q7,W7) -> 0 | AD7: =SUM(M7,S7,Y7) -> 0 | AF7: 미용티슈 | AM7: Ilimsk | AO7: WET(LBKP)
C8: Acacia | D8: 250 | G8: =SUM(Z8,AB8,AD8) -> 49500 | H8: 77 | I8: =H8*D8 -> 19250 | K8: =D8*J8 -> 0 | M8: =D8*L8 -> 0 | N8: 66 | O8: =D8*N8 -> 16500 | Q8: =D8*P8 -> 0 | S8: =D8*R8 -> 0 | T8: 55 | U8: =D8*T8 -> 13750 | W8: =D8*V8 -> 0 | Y8: =D8*X8 -> 0 | Z8: =SUM(I8,O8,U8) -> 49500 | AB8: =SUM(K8,Q8,W8) -> 0 | AD8: =SUM(M8,S8,Y8) -> 0 | AF8: 3R | AM8: 크라프튼 | AO8: 0
C9: 수자노 | D9: 249 | G9: =SUM(Z9,AB9,AD9) -> 0 | I9: =H9*D9 -> 0 | K9: =D9*J9 -> 0 | M9: =D9*L9 -> 0 | O9: =D9*N9 -> 0 | Q9: =D9*P9 -> 0 | S9: =D9*R9 -> 0 | U9: =D9*T9 -> 0 | W9: =D9*V9 -> 0 | Y9: =D9*X9 -> 0 | Z9: =SUM(I9,O9,U9) -> 0 | AB9: =SUM(K9,Q9,W9) -> 0 | AD9: =SUM(M9,S9,Y9) -> 0 | AM9: 비랄 | AO9: 0
C10: 소계 | E10: =SUM(E6:E9) -> 0 | F10: =SUM(F6:F9) -> 0 | G10: =SUM(G6:G9) -> 49500 | I10: =SUM(I6:I9) -> 19250 | K10: =SUM(K6:K9) -> 0 | M10: =SUM(M6:M9) -> 0 | O10: =SUM(O6:O9) -> 16500 | Q10: =SUM(Q6:Q9) -> 0 | S10: =SUM(S6:S9) -> 0 | U10: =SUM(U6:U9) -> 13750 | W10: =SUM(W6:W9) -> 0 | Y10: =SUM(Y6:Y9) -> 0 | Z10: =SUM(Z6:Z9) -> 49500 | AB10: =SUM(AB6:AB9) -> 0 | AD10: =SUM(AD6:AD9) -> 0 | AM10: Arauco | AO10: 0
B11: NBKP | C11: 피스리버 | G11: =SUM(Z11,AB11,AD11) -> 0 | I11: =H11*D11 -> 0 | K11: =D11*J11 -> 0 | M11: =D11*L11 -> 0 | O11: =D11*N11 -> 0 | Q11: =D11*P11 -> 0 | S11: =D11*R11 -> 0 | U11: =D11*T11 -> 0 | W11: =D11*V11 -> 0 | Y11: =D11*X11 -> 0 | Z11: =SUM(I11,O11,U11) -> 0 | AA11: =IFERROR(1-AA6,"") -> 0.083027676 | AB11: =SUM(K11,Q11,W11) -> 0 | AC11: =IFERROR(1-AC6,"") | AD11: =SUM(M11,S11,Y11) -> 0 | AE11: =IFERROR(1-AE6,"") | AM11: 하우사운드
C12: Ilimsk | G12: =SUM(Z12,AB12,AD12) -> 0 | I12: =H12*D12 -> 0 | K12: =D12*J12 -> 0 | M12: =D12*L12 -> 0 | O12: =D12*N12 -> 0 | Q12: =D12*P12 -> 0 | S12: =D12*R12 -> 0 | U12: =D12*T12 -> 0 | W12: =D12*V12 -> 0 | Y12: =D12*X12 -> 0 | Z12: =SUM(I12,O12,U12) -> 0 | AB12: =SUM(K12,Q12,W12) -> 0 | AD12: =SUM(M12,S12,Y12) -> 0 | AM12: 일림
C13: 멧자 | D13: 249 | G13: =SUM(Z13,AB13,AD13) -> 4482 | H13: 7 | I13: =H13*D13 -> 1743 | K13: =D13*J13 -> 0 | M13: =D13*L13 -> 0 | N13: 6 | O13: =D13*N13 -> 1494 | Q13: =D13*P13 -> 0 | S13: =D13*R13 -> 0 | T13: 5 | U13: =D13*T13 -> 1245 | W13: =D13*V13 -> 0 | Y13: =D13*X13 -> 0 | Z13: =SUM(I13,O13,U13) -> 4482 | AB13: =SUM(K13,Q13,W13) -> 0 | AD13: =SUM(M13,S13,Y13) -> 0 | AM13: 피스리버
C14: WET PULP | D14: 150 | G14: =SUM(Z14,AB14,AD14) -> 0 | I14: =H14*D14 -> 0 | K14: =D14*J14 -> 0 | M14: =D14*L14 -> 0 | O14: =D14*N14 -> 0 | Q14: =D14*P14 -> 0 | S14: =D14*R14 -> 0 | U14: =D14*T14 -> 0 | W14: =D14*V14 -> 0 | Y14: =D14*X14 -> 0 | Z14: =SUM(I14,O14,U14) -> 0 | AB14: =SUM(K14,Q14,W14) -> 0 | AD14: =SUM(M14,S14,Y14) -> 0
C15: 소계 | E15: =SUM(E11:E14) -> 0 | F15: =SUM(F11:F14) -> 0 | G15: =SUM(G11:G14) -> 4482 | I15: =SUM(I11:I14) -> 1743 | K15: =SUM(K11:K14) -> 0 | M15: =SUM(M11:M14) -> 0 | O15: =SUM(O11:O14) -> 1494 | Q15: =SUM(Q11:Q14) -> 0 | S15: =SUM(S11:S14) -> 0 | U15: =SUM(U11:U14) -> 1245 | W15: =SUM(W11:W14) -> 0 | Y15: =SUM(Y11:Y14) -> 0 | Z15: =SUM(Z11:Z14) -> 4482 | AB15: =SUM(AB11:AB14) -> 0 | AD15: =SUM(AD11:AD14) -> 0
B16: 펄프 합계 | E16: =SUM(E15,E10) -> 0 | F16: =SUM(F15,F10) -> 0 | G16: =SUM(G10,G15) -> 53982 | H16: =SUM(H15,H10) -> 0 | I16: =SUM(I15,I10) -> 20993 | J16: =SUM(J15,J10) -> 0 | K16: =SUM(K15,K10) -> 0 | L16: =SUM(L15,L10) -> 0 | M16: =SUM(M15,M10) -> 0 | N16: =SUM(N15,N10) -> 0 | O16: =SUM(O15,O10) -> 17994 | ... Z16: =SUM(Z15,Z10) -> 53982 | AB16: =SUM(AB15,AB10) -> 0 | AD16: =SUM(AD15,AD10) -> 0
B27: 2. 원료 관리 현황
B28: 구분 | D28: 펄프 종류 | G28: N-PULP(Soft Wood) | Q28: L-PULP(Hard Wood) | AA28: 비고
D29: 브랜드 명 | G29: 피스리버 | I29: 멧자 | M29: 일림 | O29: WET PULP | S29: Guaiba | U29: 수자노 | W29: WET(LBKP) | Y29: 아카시아APP
D30: 전일 이월량 | G30: ='1'!G42:H42 -> 0 | I30: ='1'!I42:J42 -> 8 | K30: ='1'!K42:L42 -> 0 | M30: ='1'!M42:N42 -> 0 | O30: ='1'!O42:P42 -> 0 | Q30: ='1'!Q42:R42 -> 0 | S30: ='1'!S42:T42 -> 0 | U30: ='1'!U42:V42 -> 0 | W30: ='1'!W42:X42 -> 0 | Y30: ='1'!Y42:Z42 -> 89
B31: 오전 | D31: 입고량 | I31: 16 | Y31: 208
D32: 사용량 | I32: 7 | Y32: 77
D33: 재고량
B34: 오후 | D34: 입고량
D35: 사용량 | I35: 6 | Y35: 66
D36: 재고량
B37: 야간 | D37: 입고량
D38: 사용량 | I38: 5 | Y38: 55
D39: 재고량
B40: 펄프 합계 | D40: 총 사용량 | G40: =SUM(G32,G35,G38) -> 0 | I40: =SUM(I32,I35,I38) -> 18 | K40: =SUM(K32,K35,K38) -> 0 | M40: =SUM(M32,M35,M38) -> 0 | O40: =SUM(O32,O35,O38) -> 0 | Q40: =SUM(Q32,Q35,Q38) -> 0 | S40: =SUM(S32,S35,S38) -> 0 | U40: =SUM(U32,U35,U38) -> 0 | W40: =SUM(W32,W35,W38) -> 0 | Y40: =SUM(Y32,Y35,Y38) -> 198
D41: 총 거래 수량 | G41: =SUM(G30,G31,G34,G37) -> 0 | I41: =SUM(I30,I31,I34,I37) -> 24 | K41: =SUM(K30,K31,K34,K37) -> 0 | M41: =SUM(M30,M31,M34,M37) -> 0 | O41: =SUM(O30,O31,O34,O37) -> 0 | Q41: =SUM(Q30,Q31,Q34,Q37) -> 0 | S41: =SUM(S30,S31,S34,S37) -> 0 | U41: =SUM(U30,U31,U34,U37) -> 0 | W41: =SUM(W30,W31,W34,W37) -> 0 | Y41: =SUM(Y30,Y31,Y34,Y37) -> 297
D42: 재고량 | G42: =G41-G40 -> 0 | I42: =I41-I40 -> 6 | K42: =K41-K40 -> 0 | M42: =M41-M40 -> 0 | O42: =O41-O40 -> 0 | Q42: =Q41-Q40 -> 0 | S42: =S41-S40 -> 0 | U42: =U41-U40 -> 0 | W42: =W41-W40 -> 0 | Y42: =Y41-Y40 -> 99

Sheet 3
B1: ◈ 원질4호기 원료처리 작업 일지 | AM1: NBKP | AO1: LBKP
B2: 1. 원료 처리 현황 | Z2: 2026 년 01 월 03 일 | AK2: 데코 | AM2: 브라츠크 | AO2: Acacia
B3: 구분 | D3: 기준 중량 (kg) | E3: 전일 재공량 | F3: 금일 재공량 | G3: 일 원료 처리량 | H3: 오전( 반) | N3: 오후( 반) | T3: 야간( 반) | Z3: 합계 | AK3: K/T | AM3: WET PULP | AO3: 수자노
H4: 데코 | N4: 데코 | T4: 데코 | Z4: 데코 | AK4: 0 | AM4: 멧자 | AO4: 아카시아APP
H5: Bale | I5: 중량 | J5: Bale | K5: 중량 | L5: Bale | M5: 중량 | N5: Bale | O5: 중량 | P5: Bale | Q5: 중량 | R5: Bale | S5: 중량 | T5: Bale | U5: 중량 | V5: Bale | W5: 중량 | X5: Bale | Y5: 중량 | Z5: 합계 | AA5: 배합비 | AB5: 합계 | AC5: 배합비 | AD5: 합계 | AE5: 배합비 | AK5: 0 | AM5: PCMC | AO5: Santafe
B6: LBKP | C6: Guaiba | D6: 247 | G6: =SUM(Z6,AB6,AD6) -> 0 | I6: =H6*D6 -> 0 | K6: =D6*J6 -> 0 | M6: =D6*L6 -> 0 | O6: =D6*N6 -> 0 | Q6: =D6*P6 -> 0 | S6: =D6*R6 -> 0 | U6: =D6*T6 -> 0 | W6: =D6*V6 -> 0 | Y6: =D6*X6 -> 0 | Z6: =SUM(I6,O6,U6) -> 0 | AA6: =IFERROR(Z10/Z16,"") -> 0.91697232 | AB6: =SUM(K6,Q6,W6) -> 0 | AC6: =IFERROR(AB10/AB16,"") | AD6: =SUM(M6,S6,Y6) -> 0 | AE6: =IFERROR(AD10/AD16,"") | AF6: 비데원지 | AM6: Pacifico | AO6: Guaiba
C7: WET(LBKP) | D7: 137 | G7: =SUM(Z7,AB7,AD7) -> 0 | I7: =H7*D7 -> 0 | K7: =D7*J7 -> 0 | M7: =D7*L7 -> 0 | O7: =D7*N7 -> 0 | Q7: =D7*P7 -> 0 | S7: =D7*R7 -> 0 | U7: =D7*T7 -> 0 | W7: =D7*V7 -> 0 | Y7: =D7*X7 -> 0 | Z7: =SUM(I7,O7,U7) -> 0 | AB7: =SUM(K7,Q7,W7) -> 0 | AD7: =SUM(M7,S7,Y7) -> 0 | AF7: 미용티슈 | AM7: Ilimsk | AO7: WET(LBKP)
C8: Acacia | D8: 250 | G8: =SUM(Z8,AB8,AD8) -> 49500 | H8: 66 | I8: =H8*D8 -> 16500 | K8: =D8*J8 -> 0 | M8: =D8*L8 -> 0 | N8: 66 | O8: =D8*N8 -> 16500 | Q8: =D8*P8 -> 0 | S8: =D8*R8 -> 0 | T8: 66 | U8: =D8*T8 -> 16500 | W8: =D8*V8 -> 0 | Y8: =D8*X8 -> 0 | Z8: =SUM(I8,O8,U8) -> 49500 | AB8: =SUM(K8,Q8,W8) -> 0 | AD8: =SUM(M8,S8,Y8) -> 0 | AF8: 3R | AM8: 크라프튼 | AO8: 0
C9: 수자노 | D9: 249 | G9: =SUM(Z9,AB9,AD9) -> 0 | I9: =H9*D9 -> 0 | K9: =D9*J9 -> 0 | M9: =D9*L9 -> 0 | O9: =D9*N9 -> 0 | Q9: =D9*P9 -> 0 | S9: =D9*R9 -> 0 | U9: =D9*T9 -> 0 | W9: =D9*V9 -> 0 | Y9: =D9*X9 -> 0 | Z9: =SUM(I9,O9,U9) -> 0 | AB9: =SUM(K9,Q9,W9) -> 0 | AD9: =SUM(M9,S9,Y9) -> 0 | AM9: 비랄 | AO9: 0
C10: 소계 | E10: =SUM(E6:E9) -> 0 | F10: =SUM(F6:F9) -> 0 | G10: =SUM(G6:G9) -> 49500 | I10: =SUM(I6:I9) -> 16500 | K10: =SUM(K6:K9) -> 0 | M10: =SUM(M6:M9) -> 0 | O10: =SUM(O6:O9) -> 16500 | Q10: =SUM(Q6:Q9) -> 0 | S10: =SUM(S6:S9) -> 0 | U10: =SUM(U6:U9) -> 16500 | W10: =SUM(W6:W9) -> 0 | Y10: =SUM(Y6:Y9) -> 0 | Z10: =SUM(Z6:Z9) -> 49500 | AB10: =SUM(AB6:AB9) -> 0 | AD10: =SUM(AD6:AD9) -> 0 | AM10: Arauco | AO10: 0
B11: NBKP | C11: 피스리버 | G11: =SUM(Z11,AB11,AD11) -> 0 | I11: =H11*D11 -> 0 | K11: =D11*J11 -> 0 | M11: =D11*L11 -> 0 | O11: =D11*N11 -> 0 | Q11: =D11*P11 -> 0 | S11: =D11*R11 -> 0 | U11: =D11*T11 -> 0 | W11: =D11*V11 -> 0 | Y11: =D11*X11 -> 0 | Z11: =SUM(I11,O11,U11) -> 0 | AA11: =IFERROR(1-AA6,"") -> 0.083027676 | AB11: =SUM(K11,Q11,W11) -> 0 | AC11: =IFERROR(1-AC6,"") | AD11: =SUM(M11,S11,Y11) -> 0 | AE11: =IFERROR(1-AE6,"") | AM11: 하우사운드
C12: Ilimsk | G12: =SUM(Z12,AB12,AD12) -> 0 | I12: =H12*D12 -> 0 | K12: =D12*J12 -> 0 | M12: =D12*L12 -> 0 | O12: =D12*N12 -> 0 | Q12: =D12*P12 -> 0 | S12: =D12*R12 -> 0 | U12: =D12*T12 -> 0 | W12: =D12*V12 -> 0 | Y12: =D12*X12 -> 0 | Z12: =SUM(I12,O12,U12) -> 0 | AB12: =SUM(K12,Q12,W12) -> 0 | AD12: =SUM(M12,S12,Y12) -> 0 | AM12: 일림
C13: 멧자 | D13: 249 | G13: =SUM(Z13,AB13,AD13) -> 4482 | H13: 6 | I13: =H13*D13 -> 1494 | K13: =D13*J13 -> 0 | M13: =D13*L13 -> 0 | N13: 6 | O13: =D13*N13 -> 1494 | Q13: =D13*P13 -> 0 | S13: =D13*R13 -> 0 | T13: 6 | U13: =D13*T13 -> 1494 | W13: =D13*V13 -> 0 | Y13: =D13*X13 -> 0 | Z13: =SUM(I13,O13,U13) -> 4482 | AB13: =SUM(K13,Q13,W13) -> 0 | AD13: =SUM(M13,S13,Y13) -> 0 | AM13: 피스리버
C14: WET PULP | D14: 150 | G14: =SUM(Z14,AB14,AD14) -> 0 | I14: =H14*D14 -> 0 | K14: =D14*J14 -> 0 | M14: =D14*L14 -> 0 | O14: =D14*N14 -> 0 | Q14: =D14*P14 -> 0 | S14: =D14*R14 -> 0 | U14: =D14*T14 -> 0 | W14: =D14*V14 -> 0 | Y14: =D14*X14 -> 0 | Z14: =SUM(I14,O14,U14) -> 0 | AB14: =SUM(K14,Q14,W14) -> 0 | AD14: =SUM(M14,S14,Y14) -> 0
C15: 소계 | E15: =SUM(E11:E14) -> 0 | F15: =SUM(F11:F14) -> 0 | G15: =SUM(G11:G14) -> 4482 | I15: =SUM(I11:I14) -> 1494 | K15: =SUM(K11:K14) -> 0 | M15: =SUM(M11:M14) -> 0 | O15: =SUM(O11:O14) -> 1494 | Q15: =SUM(Q11:Q14) -> 0 | S15: =SUM(S11:S14) -> 0 | U15: =SUM(U11:U14) -> 1494 | W15: =SUM(W11:W14) -> 0 | Y15: =SUM(Y11:Y14) -> 0 | Z15: =SUM(Z11:Z14) -> 4482 | AB15: =SUM(AB11:AB14) -> 0 | AD15: =SUM(AD11:AD14) -> 0
B16: 펄프 합계 | E16: =SUM(E15,E10) -> 0 | F16: =SUM(F15,F10) -> 0 | G16: =SUM(G10,G15) -> 53982 | H16: =SUM(H15,H10) -> 0 | I16: =SUM(I15,I10) -> 17994 | J16: =SUM(J15,J10) -> 0 | K16: =SUM(K15,K10) -> 0 | L16: =SUM(L15,L10) -> 0 | M16: =SUM(M15,M10) -> 0 | N16: =SUM(N15,N10) -> 0 | O16: =SUM(O15,O10) -> 17994 | ... Z16: =SUM(Z15,Z10) -> 53982 | AB16: =SUM(AB15,AB10) -> 0 | AD16: =SUM(AD15,AD10) -> 0
B27: 2. 원료 관리 현황
B28: 구분 | D28: 펄프 종류 | G28: N-PULP(Soft Wood) | Q28: L-PULP(Hard Wood) | AA28: 비고
D29: 브랜드 명 | G29: 피스리버 | I29: 멧자 | M29: 일림 | O29: WET PULP | S29: Guaiba | U29: 수자노 | W29: WET(LBKP) | Y29: 아카시아APP
D30: 전일 이월량 | G30: ='2'!G42:H42 -> 0 | I30: ='2'!I42:J42 -> 6 | K30: ='2'!K42:L42 -> 0 | M30: ='2'!M42:N42 -> 0 | O30: ='2'!O42:P42 -> 0 | Q30: ='2'!Q42:R42 -> 0 | S30: ='2'!S42:T42 -> 0 | U30: ='2'!U42:V42 -> 0 | W30: ='2'!W42:X42 -> 0 | Y30: ='2'!Y42:Z42 -> 99
B31: 오전 | D31: 입고량 | I31: 16 | Y31: 192
D32: 사용량 | I32: 6 | Y32: 66
D33: 재고량
B34: 오후 | D34: 입고량
D35: 사용량 | I35: 6 | Y35: 66
D36: 재고량
B37: 야간 | D37: 입고량
D38: 사용량 | I38: 6 | Y38: 66
D39: 재고량
B40: 펄프 합계 | D40: 총 사용량 | G40: =SUM(G32,G35,G38) -> 0 | I40: =SUM(I32,I35,I38) -> 18 | K40: =SUM(K32,K35,K38) -> 0 | M40: =SUM(M32,M35,M38) -> 0 | O40: =SUM(O32,O35,O38) -> 0 | Q40: =SUM(Q32,Q35,Q38) -> 0 | S40: =SUM(S32,S35,S38) -> 0 | U40: =SUM(U32,U35,U38) -> 0 | W40: =SUM(W32,W35,W38) -> 0 | Y40: =SUM(Y32,Y35,Y38) -> 198
D41: 총 거래 수량 | G41: =SUM(G30,G31,G34,G37) -> 0 | I41: =SUM(I30,I31,I34,I37) -> 22 | K41: =SUM(K30,K31,K34,K37) -> 0 | M41: =SUM(M30,M31,M34,M37) -> 0 | O41: =SUM(O30,O31,O34,O37) -> 0 | Q41: =SUM(Q30,Q31,Q34,Q37) -> 0 | S41: =SUM(S30,S31,S34,S37) -> 0 | U41: =SUM(U30,U31,U34,U37) -> 0 | W41: =SUM(W30,W31,W34,W37) -> 0 | Y41: =SUM(Y30,Y31,Y34,Y37) -> 291
D42: 재고량 | G42: =G41-G40 -> 0 | I42: =I41-I40 -> 4 | K42: =K41-K40 -> 0 | M42: =M41-M40 -> 0 | O42: =O41-O40 -> 0 | Q42: =Q41-Q40 -> 0 | S42: =S41-S40 -> 0 | U42: =U41-U40 -> 0 | W42: =W41-W40 -> 0 | Y42: =Y41-Y40 -> 93

Sheet 4
B1: ◈ 원질4호기 원료처리 작업 일지 | AM1: NBKP | AO1: LBKP
B2: 1. 원료 처리 현황 | Z2: 2026 년 01 월 04 일 | AK2: 데코 | AM2: 브라츠크 | AO2: Acacia
B3: 구분 | D3: 기준 중량 (kg) | E3: 전일 재공량 | F3: 금일 재공량 | G3: 일 원료 처리량 | H3: 오전( 반) | N3: 오후( 반) | T3: 야간( 반) | Z3: 합계 | AK3: K/T | AM3: WET PULP | AO3: 수자노
H4: 데코 | N4: 데코 | T4: 데코 | Z4: 데코 | AK4: 0 | AM4: 멧자 | AO4: 아카시아APP
H5: Bale | I5: 중량 | J5: Bale | K5: 중량 | L5: Bale | M5: 중량 | N5: Bale | O5: 중량 | P5: Bale | Q5: 중량 | R5: Bale | S5: 중량 | T5: Bale | U5: 중량 | V5: Bale | W5: 중량 | X5: Bale | Y5: 중량 | Z5: 합계 | AA5: 배합비 | AB5: 합계 | AC5: 배합비 | AD5: 합계 | AE5: 배합비 | AK5: 0 | AM5: PCMC | AO5: Santafe
B6: LBKP | C6: Guaiba | D6: 247 | G6: =SUM(Z6,AB6,AD6) -> 0 | I6: =H6*D6 -> 0 | K6: =D6*J6 -> 0 | M6: =D6*L6 -> 0 | O6: =D6*N6 -> 0 | Q6: =D6*P6 -> 0 | S6: =D6*R6 -> 0 | U6: =D6*T6 -> 0 | W6: =D6*V6 -> 0 | Y6: =D6*X6 -> 0 | Z6: =SUM(I6,O6,U6) -> 0 | AA6: =IFERROR(Z10/Z16,"") -> 0.91248276 | AB6: =SUM(K6,Q6,W6) -> 0 | AC6: =IFERROR(AB10/AB16,"") | AD6: =SUM(M6,S6,Y6) -> 0 | AE6: =IFERROR(AD10/AD16,"") | AF6: 비데원지 | AM6: Pacifico | AO6: Guaiba
C7: WET(LBKP) | D7: 137 | G7: =SUM(Z7,AB7,AD7) -> 0 | I7: =H7*D7 -> 0 | K7: =D7*J7 -> 0 | M7: =D7*L7 -> 0 | O7: =D7*N7 -> 0 | Q7: =D7*P7 -> 0 | S7: =D7*R7 -> 0 | U7: =D7*T7 -> 0 | W7: =D7*V7 -> 0 | Y7: =D7*X7 -> 0 | Z7: =SUM(I7,O7,U7) -> 0 | AB7: =SUM(K7,Q7,W7) -> 0 | AD7: =SUM(M7,S7,Y7) -> 0 | AF7: 미용티슈 | AM7: Ilimsk | AO7: WET(LBKP)
C8: Acacia | D8: 250 | G8: =SUM(Z8,AB8,AD8) -> 33750 | H8: 77 | I8: =H8*D8 -> 19250 | K8: =D8*J8 -> 0 | M8: =D8*L8 -> 0 | N8: 55 | O8: =D8*N8 -> 13750 | Q8: =D8*P8 -> 0 | S8: =D8*R8 -> 0 | T8: 3 | U8: =D8*T8 -> 750 | W8: =D8*V8 -> 0 | Y8: =D8*X8 -> 0 | Z8: =SUM(I8,O8,U8) -> 33750 | AB8: =SUM(K8,Q8,W8) -> 0 | AD8: =SUM(M8,S8,Y8) -> 0 | AF8: 3R | AM8: 크라프튼 | AO8: 0
C9: 수자노 | D9: 249 | G9: =SUM(Z9,AB9,AD9) -> 0 | I9: =H9*D9 -> 0 | K9: =D9*J9 -> 0 | M9: =D9*L9 -> 0 | O9: =D9*N9 -> 0 | Q9: =D9*P9 -> 0 | S9: =D9*R9 -> 0 | U9: =D9*T9 -> 0 | W9: =D9*V9 -> 0 | Y9: =D9*X9 -> 0 | Z9: =SUM(I9,O9,U9) -> 0 | AB9: =SUM(K9,Q9,W9) -> 0 | AD9: =SUM(M9,S9,Y9) -> 0 | AM9: 비랄 | AO9: 0
C10: 소계 | E10: =SUM(E6:E9) -> 0 | F10: =SUM(F6:F9) -> 0 | G10: =SUM(G6:G9) -> 33750 | I10: =SUM(I6:I9) -> 19250 | K10: =SUM(K6:K9) -> 0 | M10: =SUM(M6:M9) -> 0 | O10: =SUM(O6:O9) -> 13750 | Q10: =SUM(Q6:Q9) -> 0 | S10: =SUM(S6:S9) -> 0 | U10: =SUM(U6:U9) -> 750 | W10: =SUM(W6:W9) -> 0 | Y10: =SUM(Y6:Y9) -> 0 | Z10: =SUM(Z6:Z9) -> 33750 | AB10: =SUM(AB6:AB9) -> 0 | AD10: =SUM(AD6:AD9) -> 0 | AM10: Arauco | AO10: 0
B11: NBKP | C11: 피스리버 | G11: =SUM(Z11,AB11,AD11) -> 0 | I11: =H11*D11 -> 0 | K11: =D11*J11 -> 0 | M11: =D11*L11 -> 0 | O11: =D11*N11 -> 0 | Q11: =D11*P11 -> 0 | S11: =D11*R11 -> 0 | U11: =D11*T11 -> 0 | W11: =D11*V11 -> 0 | Y11: =D11*X11 -> 0 | Z11: =SUM(I11,O11,U11) -> 0 | AA11: =IFERROR(1-AA6,"") -> 0.087517236 | AB11: =SUM(K11,Q11,W11) -> 0 | AC11: =IFERROR(1-AC6,"") | AD11: =SUM(M11,S11,Y11) -> 0 | AE11: =IFERROR(1-AE6,"") | AM11: 하우사운드
C12: Ilimsk | G12: =SUM(Z12,AB12,AD12) -> 0 | I12: =H12*D12 -> 0 | K12: =D12*J12 -> 0 | M12: =D12*L12 -> 0 | O12: =D12*N12 -> 0 | Q12: =D12*P12 -> 0 | S12: =D12*R12 -> 0 | U12: =D12*T12 -> 0 | W12: =D12*V12 -> 0 | Y12: =D12*X12 -> 0 | Z12: =SUM(I12,O12,U12) -> 0 | AB12: =SUM(K12,Q12,W12) -> 0 | AD12: =SUM(M12,S12,Y12) -> 0 | AM12: 일림
C13: 멧자 | D13: 249 | G13: =SUM(Z13,AB13,AD13) -> 3237 | H13: 7 | I13: =H13*D13 -> 1743 | K13: =D13*J13 -> 0 | M13: =D13*L13 -> 0 | N13: 5 | O13: =D13*N13 -> 1245 | Q13: =D13*P13 -> 0 | S13: =D13*R13 -> 0 | T13: 1 | U13: =D13*T13 -> 249 | W13: =D13*V13 -> 0 | Y13: =D13*X13 -> 0 | Z13: =SUM(I13,O13,U13) -> 3237 | AB13: =SUM(K13,Q13,W13) -> 0 | AD13: =SUM(M13,S13,Y13) -> 0 | AM13: 피스리버
C14: WET PULP | D14: 150 | G14: =SUM(Z14,AB14,AD14) -> 0 | I14: =H14*D14 -> 0 | K14: =D14*J14 -> 0 | M14: =D14*L14 -> 0 | O14: =D14*N14 -> 0 | Q14: =D14*P14 -> 0 | S14: =D14*R14 -> 0 | U14: =D14*T14 -> 0 | W14: =D14*V14 -> 0 | Y14: =D14*X14 -> 0 | Z14: =SUM(I14,O14,U14) -> 0 | AB14: =SUM(K14,Q14,W14) -> 0 | AD14: =SUM(M14,S14,Y14) -> 0
C15: 소계 | E15: =SUM(E11:E14) -> 0 | F15: =SUM(F11:F14) -> 0 | G15: =SUM(G11:G14) -> 3237 | I15: =SUM(I11:I14) -> 1743 | K15: =SUM(K11:K14) -> 0 | M15: =SUM(M11:M14) -> 0 | O15: =SUM(O11:O14) -> 1245 | Q15: =SUM(Q11:Q14) -> 0 | S15: =SUM(S11:S14) -> 0 | U15: =SUM(U11:U14) -> 249 | W15: =SUM(W11:W14) -> 0 | Y15: =SUM(Y11:Y14) -> 0 | Z15: =SUM(Z11:Z14) -> 3237 | AB15: =SUM(AB11:AB14) -> 0 | AD15: =SUM(AD11:AD14) -> 0
B16: 펄프 합계 | E16: =SUM(E15,E10) -> 0 | F16: =SUM(F15,F10) -> 0 | G16: =SUM(G10,G15) -> 36987 | H16: =SUM(H15,H10) -> 0 | I16: =SUM(I15,I10) -> 20993 | J16: =SUM(J15,J10) -> 0 | K16: =SUM(K15,K10) -> 0 | L16: =SUM(L15,L10) -> 0 | M16: =SUM(M15,M10) -> 0 | N16: =SUM(N15,N10) -> 0 | O16: =SUM(O15,O10) -> 14995 | ... Z16: =SUM(Z15,Z10) -> 36987 | AB16: =SUM(AB15,AB10) -> 0 | AD16: =SUM(AD15,AD10) -> 0
B27: 2. 원료 관리 현황
B28: 구분 | D28: 펄프 종류 | G28: N-PULP(Soft Wood) | Q28: L-PULP(Hard Wood) | AA28: 비고
D29: 브랜드 명 | G29: 피스리버 | I29: 멧자 | M29: 일림 | O29: WET PULP | S29: Guaiba | U29: 수자노 | W29: WET(LBKP) | Y29: 아카시아APP
D30: 전일 이월량 | G30: ='3'!G42:H42 -> 0 | I30: ='3'!I42:J42 -> 4 | K30: ='3'!K42:L42 -> 0 | M30: ='3'!M42:N42 -> 0 | O30: ='3'!O42:P42 -> 0 | Q30: ='3'!Q42:R42 -> 0 | S30: ='3'!S42:T42 -> 0 | U30: ='3'!U42:V42 -> 0 | W30: ='3'!W42:X42 -> 0 | Y30: ='3'!Y42:Z42 -> 93
B31: 오전 | D31: 입고량 | I31: 32 | Y31: 192
D32: 사용량 | I32: 7 | Y32: 77
D33: 재고량
B34: 오후 | D34: 입고량
D35: 사용량 | I35: 5 | Y35: 55
D36: 재고량
B37: 야간 | D37: 입고량
D38: 사용량 | I38: 1 | Y38: 3
D39: 재고량
B40: 펄프 합계 | D40: 총 사용량 | G40: =SUM(G32,G35,G38) -> 0 | I40: =SUM(I32,I35,I38) -> 13 | K40: =SUM(K32,K35,K38) -> 0 | M40: =SUM(M32,M35,M38) -> 0 | O40: =SUM(O32,O35,O38) -> 0 | Q40: =SUM(Q32,Q35,Q38) -> 0 | S40: =SUM(S32,S35,S38) -> 0 | U40: =SUM(U32,U35,U38) -> 0 | W40: =SUM(W32,W35,W38) -> 0 | Y40: =SUM(Y32,Y35,Y38) -> 135
D41: 총 거래 수량 | G41: =SUM(G30,G31,G34,G37) -> 0 | I41: =SUM(I30,I31,I34,I37) -> 36 | K41: =SUM(K30,K31,K34,K37) -> 0 | M41: =SUM(M30,M31,M34,M37) -> 0 | O41: =SUM(O30,O31,O34,O37) -> 0 | Q41: =SUM(Q30,Q31,Q34,Q37) -> 0 | S41: =SUM(S30,S31,S34,S37) -> 0 | U41: =SUM(U30,U31,U34,U37) -> 0 | W41: =SUM(W30,W31,W34,W37) -> 0 | Y41: =SUM(Y30,Y31,Y34,Y37) -> 285
D42: 재고량 | G42: =G41-G40 -> 0 | I42: =I41-I40 -> 23 | K42: =K41-K40 -> 0 | M42: =M41-M40 -> 0 | O42: =O41-O40 -> 0 | Q42: =Q41-Q40 -> 0 | S42: =S41-S40 -> 0 | U42: =U41-U40 -> 0 | W42: =W41-W40 -> 0 | Y42: =Y41-Y40 -> 150

Sheet 5
B1: ◈ 원질4호기 원료처리 작업 일지 | AM1: NBKP | AO1: LBKP
B2: 1. 원료 처리 현황 | Z2: 2026 년 01 월 05 일 | AK2: 데코 | AM2: 브라츠크 | AO2: Acacia
B3: 구분 | D3: 기준 중량 (kg) | E3: 전일 재공량 | F3: 금일 재공량 | G3: 일 원료 처리량 | H3: 오전( 반) | N3: 오후( 반) | T3: 야간( 반) | Z3: 합계 | AK3: K/T | AM3: WET PULP | AO3: 수자노
H4: 데코 | N4: 데코 | T4: 데코 | Z4: 데코 | AK4: 0 | AM4: 멧자 | AO4: 아카시아APP
H5: Bale | I5: 중량 | J5: Bale | K5: 중량 | L5: Bale | M5: 중량 | N5: Bale | O5: 중량 | P5: Bale | Q5: 중량 | R5: Bale | S5: 중량 | T5: Bale | U5: 중량 | V5: Bale | W5: 중량 | X5: Bale | Y5: 중량 | Z5: 합계 | AA5: 배합비 | AB5: 합계 | AC5: 배합비 | AD5: 합계 | AE5: 배합비 | AK5: 0 | AM5: PCMC | AO5: Santafe
B6: LBKP | C6: Guaiba | D6: 247 | G6: =SUM(Z6,AB6,AD6) -> 0 | I6: =H6*D6 -> 0 | K6: =D6*J6 -> 0 | M6: =D6*L6 -> 0 | O6: =D6*N6 -> 0 | Q6: =D6*P6 -> 0 | S6: =D6*R6 -> 0 | U6: =D6*T6 -> 0 | W6: =D6*V6 -> 0 | Y6: =D6*X6 -> 0 | Z6: =SUM(I6,O6,U6) -> 0 | AA6: =IFERROR(Z10/Z16,"") | AB6: =SUM(K6,Q6,W6) -> 0 | AC6: =IFERROR(AB10/AB16,"") | AD6: =SUM(M6,S6,Y6) -> 0 | AE6: =IFERROR(AD10/AD16,"") | AF6: 비데원지 | AM6: Pacifico | AO6: Guaiba
C7: WET(LBKP) | D7: 137 | G7: =SUM(Z7,AB7,AD7) -> 0 | I7: =H7*D7 -> 0 | K7: =D7*J7 -> 0 | M7: =D7*L7 -> 0 | O7: =D7*N7 -> 0 | Q7: =D7*P7 -> 0 | S7: =D7*R7 -> 0 | U7: =D7*T7 -> 0 | W7: =D7*V7 -> 0 | Y7: =D7*X7 -> 0 | Z7: =SUM(I7,O7,U7) -> 0 | AB7: =SUM(K7,Q7,W7) -> 0 | AD7: =SUM(M7,S7,Y7) -> 0 | AF7: 미용티슈 | AM7: Ilimsk | AO7: WET(LBKP)
C8: Acacia | D8: 250 | G8: =SUM(Z8,AB8,AD8) -> 0 | I8: =H8*D8 -> 0 | K8: =D8*J8 -> 0 | M8: =D8*L8 -> 0 | O8: =D8*N8 -> 0 | Q8: =D8*P8 -> 0 | S8: =D8*R8 -> 0 | U8: =D8*T8 -> 0 | W8: =D8*V8 -> 0 | Y8: =D8*X8 -> 0 | Z8: =SUM(I8,O8,U8) -> 0 | AB8: =SUM(K8,Q8,W8) -> 0 | AD8: =SUM(M8,S8,Y8) -> 0 | AF8: 3R | AM8: 크라프튼 | AO8: 0
C9: 수자노 | D9: 249 | G9: =SUM(Z9,AB9,AD9) -> 0 | I9: =H9*D9 -> 0 | K9: =D9*J9 -> 0 | M9: =D9*L9 -> 0 | O9: =D9*N9 -> 0 | Q9: =D9*P9 -> 0 | S9: =D9*R9 -> 0 | U9: =D9*T9 -> 0 | W9: =D9*V9 -> 0 | Y9: =D9*X9 -> 0 | Z9: =SUM(I9,O9,U9) -> 0 | AB9: =SUM(K9,Q9,W9) -> 0 | AD9: =SUM(M9,S9,Y9) -> 0 | AM9: 비랄 | AO9: 0
C10: 소계 | E10: =SUM(E6:E9) -> 0 | F10: =SUM(F6:F9) -> 0 | G10: =SUM(G6:G9) -> 0 | I10: =SUM(I6:I9) -> 0 | K10: =SUM(K6:K9) -> 0 | M10: =SUM(M6:M9) -> 0 | O10: =SUM(O6:O9) -> 0 | Q10: =SUM(Q6:Q9) -> 0 | S10: =SUM(S6:S9) -> 0 | U10: =SUM(U6:U9) -> 0 | W10: =SUM(W6:W9) -> 0 | Y10: =SUM(Y6:Y9) -> 0 | Z10: =SUM(Z6:Z9) -> 0 | AB10: =SUM(AB6:AB9) -> 0 | AD10: =SUM(AD6:AD9) -> 0 | AM10: Arauco | AO10: 0
B11: NBKP | C11: 피스리버 | G11: =SUM(Z11,AB11,AD11) -> 0 | I11: =H11*D11 -> 0 | K11: =D11*J11 -> 0 | M11: =D11*L11 -> 0 | O11: =D11*N11 -> 0 | Q11: =D11*P11 -> 0 | S11: =D11*R11 -> 0 | U11: =D11*T11 -> 0 | W11: =D11*V11 -> 0 | Y11: =D11*X11 -> 0 | Z11: =SUM(I11,O11,U11) -> 0 | AA11: =IFERROR(1-AA6,"") | AB11: =SUM(K11,Q11,W11) -> 0 | AC11: =IFERROR(1-AC6,"") | AD11: =SUM(M11,S11,Y11) -> 0 | AE11: =IFERROR(1-AE6,"") | AM11: 하우사운드
C12: Ilimsk | G12: =SUM(Z12,AB12,AD12) -> 0 | I12: =H12*D12 -> 0 | K12: =D12*J12 -> 0 | M12: =D12*L12 -> 0 | O12: =D12*N12 -> 0 | Q12: =D12*P12 -> 0 | S12: =D12*R12 -> 0 | U12: =D12*T12 -> 0 | W12: =D12*V12 -> 0 | Y12: =D12*X12 -> 0 | Z12: =SUM(I12,O12,U12) -> 0 | AB12: =SUM(K12,Q12,W12) -> 0 | AD12: =SUM(M12,S12,Y12) -> 0 | AM12: 일림
C13: 멧자 | D13: 249 | G13: =SUM(Z13,AB13,AD13) -> 0 | I13: =H13*D13 -> 0 | K13: =D13*J13 -> 0 | M13: =D13*L13 -> 0 | O13: =D13*N13 -> 0 | Q13: =D13*P13 -> 0 | S13: =D13*R13 -> 0 | U13: =D13*T13 -> 0 | W13: =D13*V13 -> 0 | Y13: =D13*X13 -> 0 | Z13: =SUM(I13,O13,U13) -> 0 | AB13: =SUM(K13,Q13,W13) -> 0 | AD13: =SUM(M13,S13,Y13) -> 0 | AM13: 피스리버
C14: WET PULP | D14: 150 | G14: =SUM(Z14,AB14,AD14) -> 0 | I14: =H14*D14 -> 0 | K14: =D14*J14 -> 0 | M14: =D14*L14 -> 0 | O14: =D14*N14 -> 0 | Q14: =D14*P14 -> 0 | S14: =D14*R14 -> 0 | U14: =D14*T14 -> 0 | W14: =D14*V14 -> 0 | Y14: =D14*X14 -> 0 | Z14: =SUM(I14,O14,U14) -> 0 | AB14: =SUM(K14,Q14,W14) -> 0 | AD14: =SUM(M14,S14,Y14) -> 0
C15: 소계 | E15: =SUM(E11:E14) -> 0 | F15: =SUM(F11:F14) -> 0 | G15: =SUM(G11:G14) -> 0 | I15: =SUM(I11:I14) -> 0 | K15: =SUM(K11:K14) -> 0 | M15: =SUM(M11:M14) -> 0 | O15: =SUM(O11:O14) -> 0 | Q15: =SUM(Q11:Q14) -> 0 | S15: =SUM(S11:S14) -> 0 | U15: =SUM(U11:U14) -> 0 | W15: =SUM(W11:W14) -> 0 | Y15: =SUM(Y11:Y14) -> 0 | Z15: =SUM(Z11:Z14) -> 0 | AB15: =SUM(AB11:AB14) -> 0 | AD15: =SUM(AD11:AD14) -> 0
B16: 펄프 합계 | E16: =SUM(E15,E10) -> 0 | F16: =SUM(F15,F10) -> 0 | G16: =SUM(G10,G15) -> 0 | H16: =SUM(H15,H10) -> 0 | I16: =SUM(I15,I10) -> 0 | J16: =SUM(J15,J10) -> 0 | K16: =SUM(K15,K10) -> 0 | L16: =SUM(L15,L10) -> 0 | M16: =SUM(M15,M10) -> 0 | N16: =SUM(N15,N10) -> 0 | O16: =SUM(O15,O10) -> 0 | ... Z16: =SUM(Z15,Z10) -> 0 | AB16: =SUM(AB15,AB10) -> 0 | AD16: =SUM(AD15,AD10) -> 0
B27: 2. 원료 관리 현황
B28: 구분 | D28: 펄프 종류 | G28: N-PULP(Soft Wood) | Q28: L-PULP(Hard Wood) | AA28: 비고
D29: 브랜드 명 | G29: 피스리버 | I29: 멧자 | M29: 일림 | O29: WET PULP | S29: Guaiba | U29: 수자노 | W29: WET(LBKP) | Y29: 아카시아APP
D30: 전일 이월량 | G30: ='4'!G42:H42 -> 0 | I30: ='4'!I42:J42 -> 23 | K30: ='4'!K42:L42 -> 0 | M30: ='4'!M42:N42 -> 0 | O30: ='4'!O42:P42 -> 0 | Q30: ='4'!Q42:R42 -> 0 | S30: ='4'!S42:T42 -> 0 | U30: ='4'!U42:V42 -> 0 | W30: ='4'!W42:X42 -> 0 | Y30: ='4'!Y42:Z42 -> 150
B31: 오전 | D31: 입고량
D32: 사용량
D33: 재고량
B34: 오후 | D34: 입고량
D35: 사용량
D36: 재고량
B37: 야간 | D37: 입고량
D38: 사용량
D39: 재고량
B40: 펄프 합계 | D40: 총 사용량 | G40: =SUM(G32,G35,G38) -> 0 | I40: =SUM(I32,I35,I38) -> 0 | K40: =SUM(K32,K35,K38) -> 0 | M40: =SUM(M32,M35,M38) -> 0 | O40: =SUM(O32,O35,O38) -> 0 | Q40: =SUM(Q32,Q35,Q38) -> 0 | S40: =SUM(S32,S35,S38) -> 0 | U40: =SUM(U32,U35,U38) -> 0 | W40: =SUM(W32,W35,W38) -> 0 | Y40: =SUM(Y32,Y35,Y38) -> 0
D41: 총 거래 수량 | G41: =SUM(G30,G31,G34,G37) -> 0 | I41: =SUM(I30,I31,I34,I37) -> 23 | K41: =SUM(K30,K31,K34,K37) -> 0 | M41: =SUM(M30,M31,M34,M37) -> 0 | O41: =SUM(O30,O31,O34,O37) -> 0 | Q41: =SUM(Q30,Q31,Q34,Q37) -> 0 | S41: =SUM(S30,S31,S34,S37) -> 0 | U41: =SUM(U30,U31,U34,U37) -> 0 | W41: =SUM(W30,W31,W34,W37) -> 0 | Y41: =SUM(Y30,Y31,Y34,Y37) -> 150
D42: 재고량 | G42: =G41-G40 -> 0 | I42: =I41-I40 -> 23 | K42: =K41-K40 -> 0 | M42: =M41-M40 -> 0 | O42: =O41-O40 -> 0 | Q42: =Q41-Q40 -> 0 | S42: =S41-S40 -> 0 | U42: =U41-U40 -> 0 | W42: =W41-W40 -> 0 | Y42: =Y41-Y40 -> 150

Sheet 6
B1: ◈ 원질4호기 원료처리 작업 일지 | AM1: NBKP | AO1: LBKP
B2: 1. 원료 처리 현황 | Z2: 2026 년 01 월 06 일 | AK2: 데코 | AM2: 브라츠크 | AO2: Acacia
B3: 구분 | D3: 기준 중량 (kg) | E3: 전일 재공량 | F3: 금일 재공량 | G3: 일 원료 처리량 | H3: 오전( 반) | N3: 오후( 반) | T3: 야간( 반) | Z3: 합계 | AK3: K/T | AM3: WET PULP | AO3: 수자노
H4: 데코 | N4: 데코 | T4: 데코 | Z4: 데코 | AK4: 0 | AM4: 멧자 | AO4: 아카시아APP
H5: Bale | I5: 중량 | J5: Bale | K5: 중량 | L5: Bale | M5: 중량 | N5: Bale | O5: 중량 | P5: Bale | Q5: 중량 | R5: Bale | S5: 중량 | T5: Bale | U5: 중량 | V5: Bale | W5: 중량 | X5: Bale | Y5: 중량 | Z5: 합계 | AA5: 배합비 | AB5: 합계 | AC5: 배합비 | AD5: 합계 | AE5: 배합비 | AK5: 0 | AM5: PCMC | AO5: Santafe
B6: LBKP | C6: Guaiba | D6: 247 | G6: =SUM(Z6,AB6,AD6) -> 0 | I6: =H6*D6 -> 0 | K6: =D6*J6 -> 0 | M6: =D6*L6 -> 0 | O6: =D6*N6 -> 0 | Q6: =D6*P6 -> 0 | S6: =D6*R6 -> 0 | U6: =D6*T6 -> 0 | W6: =D6*V6 -> 0 | Y6: =D6*X6 -> 0 | Z6: =SUM(I6,O6,U6) -> 0 | AA6: =IFERROR(Z10/Z16,"") | AB6: =SUM(K6,Q6,W6) -> 0 | AC6: =IFERROR(AB10/AB16,"") | AD6: =SUM(M6,S6,Y6) -> 0 | AE6: =IFERROR(AD10/AD16,"") | AF6: 비데원지 | AM6: Pacifico | AO6: Guaiba
C7: WET(LBKP) | D7: 137 | G7: =SUM(Z7,AB7,AD7) -> 0 | I7: =H7*D7 -> 0 | K7: =D7*J7 -> 0 | M7: =D7*L7 -> 0 | O7: =D7*N7 -> 0 | Q7: =D7*P7 -> 0 | S7: =D7*R7 -> 0 | U7: =D7*T7 -> 0 | W7: =D7*V7 -> 0 | Y7: =D7*X7 -> 0 | Z7: =SUM(I7,O7,U7) -> 0 | AB7: =SUM(K7,Q7,W7) -> 0 | AD7: =SUM(M7,S7,Y7) -> 0 | AF7: 미용티슈 | AM7: Ilimsk | AO7: WET(LBKP)
C8: Acacia | D8: 250 | G8: =SUM(Z8,AB8,AD8) -> 0 | I8: =H8*D8 -> 0 | K8: =D8*J8 -> 0 | M8: =D8*L8 -> 0 | O8: =D8*N8 -> 0 | Q8: =D8*P8 -> 0 | S8: =D8*R8 -> 0 | U8: =D8*T8 -> 0 | W8: =D8*V8 -> 0 | Y8: =D8*X8 -> 0 | Z8: =SUM(I8,O8,U8) -> 0 | AB8: =SUM(K8,Q8,W8) -> 0 | AD8: =SUM(M8,S8,Y8) -> 0 | AF8: 3R | AM8: 크라프튼 | AO8: 0
C9: 수자노 | D9: 249 | G9: =SUM(Z9,AB9,AD9) -> 0 | I9: =H9*D9 -> 0 | K9: =D9*J9 -> 0 | M9: =D9*L9 -> 0 | O9: =D9*N9 -> 0 | Q9: =D9*P9 -> 0 | S9: =D9*R9 -> 0 | U9: =D9*T9 -> 0 | W9: =D9*V9 -> 0 | Y9: =D9*X9 -> 0 | Z9: =SUM(I9,O9,U9) -> 0 | AB9: =SUM(K9,Q9,W9) -> 0 | AD9: =SUM(M9,S9,Y9) -> 0 | AM9: 비랄 | AO9: 0
C10: 소계 | E10: =SUM(E6:E9) -> 0 | F10: =SUM(F6:F9) -> 0 | G10: =SUM(G6:G9) -> 0 | I10: =SUM(I6:I9) -> 0 | K10: =SUM(K6:K9) -> 0 | M10: =SUM(M6:M9) -> 0 | O10: =SUM(O6:O9) -> 0 | Q10: =SUM(Q6:Q9) -> 0 | S10: =SUM(S6:S9) -> 0 | U10: =SUM(U6:U9) -> 0 | W10: =SUM(W6:W9) -> 0 | Y10: =SUM(Y6:Y9) -> 0 | Z10: =SUM(Z6:Z9) -> 0 | AB10: =SUM(AB6:AB9) -> 0 | AD10: =SUM(AD6:AD9) -> 0 | AM10: Arauco | AO10: 0
B11: NBKP | C11: 피스리버 | G11: =SUM(Z11,AB11,AD11) -> 0 | I11: =H11*D11 -> 0 | K11: =D11*J11 -> 0 | M11: =D11*L11 -> 0 | O11: =D11*N11 -> 0 | Q11: =D11*P11 -> 0 | S11: =D11*R11 -> 0 | U11: =D11*T11 -> 0 | W11: =D11*V11 -> 0 | Y11: =D11*X11 -> 0 | Z11: =SUM(I11,O11,U11) -> 0 | AA11: =IFERROR(1-AA6,"") | AB11: =SUM(K11,Q11,W11) -> 0 | AC11: =IFERROR(1-AC6,"") | AD11: =SUM(M11,S11,Y11) -> 0 | AE11: =IFERROR(1-AE6,"") | AM11: 하우사운드
C12: Ilimsk | G12: =SUM(Z12,AB12,AD12) -> 0 | I12: =H12*D12 -> 0 | K12: =D12*J12 -> 0 | M12: =D12*L12 -> 0 | O12: =D12*N12 -> 0 | Q12: =D12*P12 -> 0 | S12: =D12*R12 -> 0 | U12: =D12*T12 -> 0 | W12: =D12*V12 -> 0 | Y12: =D12*X12 -> 0 | Z12: =SUM(I12,O12,U12) -> 0 | AB12: =SUM(K12,Q12,W12) -> 0 | AD12: =SUM(M12,S12,Y12) -> 0 | AM12: 일림
C13: 멧자 | D13: 249 | G13: =SUM(Z13,AB13,AD13) -> 0 | I13: =H13*D13 -> 0 | K13: =D13*J13 -> 0 | M13: =D13*L13 -> 0 | O13: =D13*N13 -> 0 | Q13: =D13*P13 -> 0 | S13: =D13*R13 -> 0 | U13: =D13*T13 -> 0 | W13: =D13*V13 -> 0 | Y13: =D13*X13 -> 0 | Z13: =SUM(I13,O13,U13) -> 0 | AB13: =SUM(K13,Q13,W13) -> 0 | AD13: =SUM(M13,S13,Y13) -> 0 | AM13: 피스리버
C14: WET PULP | D14: 150 | G14: =SUM(Z14,AB14,AD14) -> 0 | I14: =H14*D14 -> 0 | K14: =D14*J14 -> 0 | M14: =D14*L14 -> 0 | O14: =D14*N14 -> 0 | Q14: =D14*P14 -> 0 | S14: =D14*R14 -> 0 | U14: =D14*T14 -> 0 | W14: =D14*V14 -> 0 | Y14: =D14*X14 -> 0 | Z14: =SUM(I14,O14,U14) -> 0 | AB14: =SUM(K14,Q14,W14) -> 0 | AD14: =SUM(M14,S14,Y14) -> 0
C15: 소계 | E15: =SUM(E11:E14) -> 0 | F15: =SUM(F11:F14) -> 0 | G15: =SUM(G11:G14) -> 0 | I15: =SUM(I11:I14) -> 0 | K15: =SUM(K11:K14) -> 0 | M15: =SUM(M11:M14) -> 0 | O15: =SUM(O11:O14) -> 0 | Q15: =SUM(Q11:Q14) -> 0 | S15: =SUM(S11:S14) -> 0 | U15: =SUM(U11:U14) -> 0 | W15: =SUM(W11:W14) -> 0 | Y15: =SUM(Y11:Y14) -> 0 | Z15: =SUM(Z11:Z14) -> 0 | AB15: =SUM(AB11:AB14) -> 0 | AD15: =SUM(AD11:AD14) -> 0
B16: 펄프 합계 | E16: =SUM(E15,E10) -> 0 | F16: =SUM(F15,F10) -> 0 | G16: =SUM(G10,G15) -> 0 | H16: =SUM(H15,H10) -> 0 | I16: =SUM(I15,I10) -> 0 | J16: =SUM(J15,J10) -> 0 | K16: =SUM(K15,K10) -> 0 | L16: =SUM(L15,L10) -> 0 | M16: =SUM(M15,M10) -> 0 | N16: =SUM(N15,N10) -> 0 | O16: =SUM(O15,O10) -> 0 | ... Z16: =SUM(Z15,Z10) -> 0 | AB16: =SUM(AB15,AB10) -> 0 | AD16: =SUM(AD15,AD10) -> 0
B27: 2. 원료 관리 현황
B28: 구분 | D28: 펄프 종류 | G28: N-PULP(Soft Wood) | Q28: L-PULP(Hard Wood) | AA28: 비고
D29: 브랜드 명 | G29: 피스리버 | I29: 멧자 | M29: 일림 | O29: WET PULP | S29: Guaiba | U29: 수자노 | W29: WET(LBKP) | Y29: 아카시아APP
D30: 전일 이월량 | G30: ='5'!G42:H42 -> 0 | I30: ='5'!I42:J42 -> 23 | K30: ='5'!K42:L42 -> 0 | M30: ='5'!M42:N42 -> 0 | O30: ='5'!O42:P42 -> 0 | Q30: ='5'!Q42:R42 -> 0 | S30: ='5'!S42:T42 -> 0 | U30: ='5'!U42:V42 -> 0 | W30: ='5'!W42:X42 -> 0 | Y30: ='5'!Y42:Z42 -> 150
B31: 오전 | D31: 입고량
D32: 사용량
D33: 재고량
B34: 오후 | D34: 입고량
D35: 사용량
D36: 재고량
B37: 야간 | D37: 입고량
D38: 사용량
D39: 재고량
B40: 펄프 합계 | D40: 총 사용량 | G40: =SUM(G32,G35,G38) -> 0 | I40: =SUM(I32,I35,I38) -> 0 | K40: =SUM(K32,K35,K38) -> 0 | M40: =SUM(M32,M35,M38) -> 0 | O40: =SUM(O32,O35,O38) -> 0 | Q40: =SUM(Q32,Q35,Q38) -> 0 | S40: =SUM(S32,S35,S38) -> 0 | U40: =SUM(U32,U35,U38) -> 0 | W40: =SUM(W32,W35,W38) -> 0 | Y40: =SUM(Y32,Y35,Y38) -> 0
D41: 총 거래 수량 | G41: =SUM(G30,G31,G34,G37) -> 0 | I41: =SUM(I30,I31,I34,I37) -> 23 | K41: =SUM(K30,K31,K34,K37) -> 0 | M41: =SUM(M30,M31,M34,M37) -> 0 | O41: =SUM(O30,O31,O34,O37) -> 0 | Q41: =SUM(Q30,Q31,Q34,Q37) -> 0 | S41: =SUM(S30,S31,S34,S37) -> 0 | U41: =SUM(U30,U31,U34,U37) -> 0 | W41: =SUM(W30,W31,W34,W37) -> 0 | Y41: =SUM(Y30,Y31,Y34,Y37) -> 150
D42: 재고량 | G42: =G41-G40 -> 0 | I42: =I41-I40 -> 23 | K42: =K41-K40 -> 0 | M42: =M41-M40 -> 0 | O42: =O41-O40 -> 0 | Q42: =Q41-Q40 -> 0 | S42: =S41-S40 -> 0 | U42: =U41-U40 -> 0 | W42: =W41-W40 -> 0 | Y42: =Y41-Y40 -> 150

Sheet 7
B1: ◈ 원질4호기 원료처리 작업 일지 | AM1: NBKP | AO1: LBKP
B2: 1. 원료 처리 현황 | Z2: 2026 년 01 월 07 일 | AK2: 데코 | AM2: 브라츠크 | AO2: Acacia
B3: 구분 | D3: 기준 중량 (kg) | E3: 전일 재공량 | F3: 금일 재공량 | G3: 일 원료 처리량 | H3: 오전( 반) | N3: 오후( 반) | T3: 야간( 반) | Z3: 합계 | AK3: K/T | AM3: WET PULP | AO3: 수자노
H4: 데코 | N4: 데코 | T4: 데코 | Z4: 데코 | AK4: 0 | AM4: 멧자 | AO4: 아카시아APP
H5: Bale | I5: 중량 | J5: Bale | K5: 중량 | L5: Bale | M5: 중량 | N5: Bale | O5: 중량 | P5: Bale | Q5: 중량 | R5: Bale | S5: 중량 | T5: Bale | U5: 중량 | V5: Bale | W5: 중량 | X5: Bale | Y5: 중량 | Z5: 합계 | AA5: 배합비 | AB5: 합계 | AC5: 배합비 | AD5: 합계 | AE5: 배합비 | AK5: 0 | AM5: PCMC | AO5: Santafe
B6: LBKP | C6: Guaiba | D6: 247 | G6: =SUM(Z6,AB6,AD6) -> 0 | I6: =H6*D6 -> 0 | K6: =D6*J6 -> 0 | M6: =D6*L6 -> 0 | O6: =D6*N6 -> 0 | Q6: =D6*P6 -> 0 | S6: =D6*R6 -> 0 | U6: =D6*T6 -> 0 | W6: =D6*V6 -> 0 | Y6: =D6*X6 -> 0 | Z6: =SUM(I6,O6,U6) -> 0 | AA6: =IFERROR(Z10/Z16,"") | AB6: =SUM(K6,Q6,W6) -> 0 | AC6: =IFERROR(AB10/AB16,"") | AD6: =SUM(M6,S6,Y6) -> 0 | AE6: =IFERROR(AD10/AD16,"") | AF6: 비데원지 | AM6: Pacifico | AO6: Guaiba
C7: WET(LBKP) | D7: 137 | G7: =SUM(Z7,AB7,AD7) -> 0 | I7: =H7*D7 -> 0 | K7: =D7*J7 -> 0 | M7: =D7*L7 -> 0 | O7: =D7*N7 -> 0 | Q7: =D7*P7 -> 0 | S7: =D7*R7 -> 0 | U7: =D7*T7 -> 0 | W7: =D7*V7 -> 0 | Y7: =D7*X7 -> 0 | Z7: =SUM(I7,O7,U7) -> 0 | AB7: =SUM(K7,Q7,W7) -> 0 | AD7: =SUM(M7,S7,Y7) -> 0 | AF7: 미용티슈 | AM7: Ilimsk | AO7: WET(LBKP)
C8: Acacia | D8: 250 | G8: =SUM(Z8,AB8,AD8) -> 0 | I8: =H8*D8 -> 0 | K8: =D8*J8 -> 0 | M8: =D8*L8 -> 0 | O8: =D8*N8 -> 0 | Q8: =D8*P8 -> 0 | S8: =D8*R8 -> 0 | U8: =D8*T8 -> 0 | W8: =D8*V8 -> 0 | Y8: =D8*X8 -> 0 | Z8: =SUM(I8,O8,U8) -> 0 | AB8: =SUM(K8,Q8,W8) -> 0 | AD8: =SUM(M8,S8,Y8) -> 0 | AF8: 3R | AM8: 크라프튼 | AO8: 0
C9: 수자노 | D9: 249 | G9: =SUM(Z9,AB9,AD9) -> 0 | I9: =H9*D9 -> 0 | K9: =D9*J9 -> 0 | M9: =D9*L9 -> 0 | O9: =D9*N9 -> 0 | Q9: =D9*P9 -> 0 | S9: =D9*R9 -> 0 | U9: =D9*T9 -> 0 | W9: =D9*V9 -> 0 | Y9: =D9*X9 -> 0 | Z9: =SUM(I9,O9,U9) -> 0 | AB9: =SUM(K9,Q9,W9) -> 0 | AD9: =SUM(M9,S9,Y9) -> 0 | AM9: 비랄 | AO9: 0
C10: 소계 | E10: =SUM(E6:E9) -> 0 | F10: =SUM(F6:F9) -> 0 | G10: =SUM(G6:G9) -> 0 | I10: =SUM(I6:I9) -> 0 | K10: =SUM(K6:K9) -> 0 | M10: =SUM(M6:M9) -> 0 | O10: =SUM(O6:O9) -> 0 | Q10: =SUM(Q6:Q9) -> 0 | S10: =SUM(S6:S9) -> 0 | U10: =SUM(U6:U9) -> 0 | W10: =SUM(W6:W9) -> 0 | Y10: =SUM(Y6:Y9) -> 0 | Z10: =SUM(Z6:Z9) -> 0 | AB10: =SUM(AB6:AB9) -> 0 | AD10: =SUM(AD6:AD9) -> 0 | AM10: Arauco | AO10: 0
B11: NBKP | C11: 피스리버 | G11: =SUM(Z11,AB11,AD11) -> 0 | I11: =H11*D11 -> 0 | K11: =D11*J11 -> 0 | M11: =D11*L11 -> 0 | O11: =D11*N11 -> 0 | Q11: =D11*P11 -> 0 | S11: =D11*R11 -> 0 | U11: =D11*T11 -> 0 | W11: =D11*V11 -> 0 | Y11: =D11*X11 -> 0 | Z11: =SUM(I11,O11,U11) -> 0 | AA11: =IFERROR(1-AA6,"") | AB11: =SUM(K11,Q11,W11) -> 0 | AC11: =IFERROR(1-AC6,"") | AD11: =SUM(M11,S11,Y11) -> 0 | AE11: =IFERROR(1-AE6,"") | AM11: 하우사운드
C12: Ilimsk | G12: =SUM(Z12,AB12,AD12) -> 0 | I12: =H12*D12 -> 0 | K12: =D12*J12 -> 0 | M12: =D12*L12 -> 0 | O12: =D12*N12 -> 0 | Q12: =D12*P12 -> 0 | S12: =D12*R12 -> 0 | U12: =D12*T12 -> 0 | W12: =D12*V12 -> 0 | Y12: =D12*X12 -> 0 | Z12: =SUM(I12,O12,U12) -> 0 | AB12: =SUM(K12,Q12,W12) -> 0 | AD12: =SUM(M12,S12,Y12) -> 0 | AM12: 일림
C13: 멧자 | D13: 249 | G13: =SUM(Z13,AB13,AD13) -> 0 | I13: =H13*D13 -> 0 | K13: =D13*J13 -> 0 | M13: =D13*L13 -> 0 | O13: =D13*N13 -> 0 | Q13: =D13*P13 -> 0 | S13: =D13*R13 -> 0 | U13: =D13*T13 -> 0 | W13: =D13*V13 -> 0 | Y13: =D13*X13 -> 0 | Z13: =SUM(I13,O13,U13) -> 0 | AB13: =SUM(K13,Q13,W13) -> 0 | AD13: =SUM(M13,S13,Y13) -> 0 | AM13: 피스리버
C14: WET PULP | D14: 150 | G14: =SUM(Z14,AB14,AD14) -> 0 | I14: =H14*D14 -> 0 | K14: =D14*J14 -> 0 | M14: =D14*L14 -> 0 | O14: =D14*N14 -> 0 | Q14: =D14*P14 -> 0 | S14: =D14*R14 -> 0 | U14: =D14*T14 -> 0 | W14: =D14*V14 -> 0 | Y14: =D14*X14 -> 0 | Z14: =SUM(I14,O14,U14) -> 0 | AB14: =SUM(K14,Q14,W14) -> 0 | AD14: =SUM(M14,S14,Y14) -> 0
C15: 소계 | E15: =SUM(E11:E14) -> 0 | F15: =SUM(F11:F14) -> 0 | G15: =SUM(G11:G14) -> 0 | I15: =SUM(I11:I14) -> 0 | K15: =SUM(K11:K14) -> 0 | M15: =SUM(M11:M14) -> 0 | O15: =SUM(O11:O14) -> 0 | Q15: =SUM(Q11:Q14) -> 0 | S15: =SUM(S11:S14) -> 0 | U15: =SUM(U11:U14) -> 0 | W15: =SUM(W11:W14) -> 0 | Y15: =SUM(Y11:Y14) -> 0 | Z15: =SUM(Z11:Z14) -> 0 | AB15: =SUM(AB11:AB14) -> 0 | AD15: =SUM(AD11:AD14) -> 0
B16: 펄프 합계 | E16: =SUM(E15,E10) -> 0 | F16: =SUM(F15,F10) -> 0 | G16: =SUM(G10,G15) -> 0 | H16: =SUM(H15,H10) -> 0 | I16: =SUM(I15,I10) -> 0 | J16: =SUM(J15,J10) -> 0 | K16: =SUM(K15,K10) -> 0 | L16: =SUM(L15,L10) -> 0 | M16: =SUM(M15,M10) -> 0 | N16: =SUM(N15,N10) -> 0 | O16: =SUM(O15,O10) -> 0 | ... Z16: =SUM(Z15,Z10) -> 0 | AB16: =SUM(AB15,AB10) -> 0 | AD16: =SUM(AD15,AD10) -> 0
B27: 2. 원료 관리 현황
B28: 구분 | D28: 펄프 종류 | G28: N-PULP(Soft Wood) | Q28: L-PULP(Hard Wood) | AA28: 비고
D29: 브랜드 명 | G29: 피스리버 | I29: 멧자 | M29: 일림 | O29: WET PULP | S29: Guaiba | U29: 수자노 | W29: WET(LBKP) | Y29: 아카시아APP
D30: 전일 이월량 | G30: ='6'!G42:H42 -> 0 | I30: ='6'!I42:J42 -> 23 | K30: ='6'!K42:L42 -> 0 | M30: ='6'!M42:N42 -> 0 | O30: ='6'!O42:P42 -> 0 | Q30: ='6'!Q42:R42 -> 0 | S30: ='6'!S42:T42 -> 0 | U30: ='6'!U42:V42 -> 0 | W30: ='6'!W42:X42 -> 0 | Y30: ='6'!Y42:Z42 -> 150
B31: 오전 | D31: 입고량
D32: 사용량
D33: 재고량
B34: 오후 | D34: 입고량
D35: 사용량
D36: 재고량
B37: 야간 | D37: 입고량
D38: 사용량
D39: 재고량
B40: 펄프 합계 | D40: 총 사용량 | G40: =SUM(G32,G35,G38) -> 0 | I40: =SUM(I32,I35,I38) -> 0 | K40: =SUM(K32,K35,K38) -> 0 | M40: =SUM(M32,M35,M38) -> 0 | O40: =SUM(O32,O35,O38) -> 0 | Q40: =SUM(Q32,Q35,Q38) -> 0 | S40: =SUM(S32,S35,S38) -> 0 | U40: =SUM(U32,U35,U38) -> 0 | W40: =SUM(W32,W35,W38) -> 0 | Y40: =SUM(Y32,Y35,Y38) -> 0
D41: 총 거래 수량 | G41: =SUM(G30,G31,G34,G37) -> 0 | I41: =SUM(I30,I31,I34,I37) -> 23 | K41: =SUM(K30,K31,K34,K37) -> 0 | M41: =SUM(M30,M31,M34,M37) -> 0 | O41: =SUM(O30,O31,O34,O37) -> 0 | Q41: =SUM(Q30,Q31,Q34,Q37) -> 0 | S41: =SUM(S30,S31,S34,S37) -> 0 | U41: =SUM(U30,U31,U34,U37) -> 0 | W41: =SUM(W30,W31,W34,W37) -> 0 | Y41: =SUM(Y30,Y31,Y34,Y37) -> 150
D42: 재고량 | G42: =G41-G40 -> 0 | I42: =I41-I40 -> 23 | K42: =K41-K40 -> 0 | M42: =M41-M40 -> 0 | O42: =O41-O40 -> 0 | Q42: =Q41-Q40 -> 0 | S42: =S41-S40 -> 0 | U42: =U41-U40 -> 0 | W42: =W41-W40 -> 0 | Y42: =Y41-Y40 -> 150

Sheet 8
B1: ◈ 원질4호기 원료처리 작업 일지 | AM1: NBKP | AO1: LBKP
B2: 1. 원료 처리 현황 | Z2: 2026 년 01 월 08 일 | AK2: 데코 | AM2: 브라츠크 | AO2: Acacia
B3: 구분 | D3: 기준 중량 (kg) | E3: 전일 재공량 | F3: 금일 재공량 | G3: 일 원료 처리량 | H3: 오전( 반) | N3: 오후( 반) | T3: 야간( 반) | Z3: 합계 | AK3: K/T | AM3: WET PULP | AO3: 수자노
H4: 데코 | N4: 데코 | T4: 데코 | Z4: 데코 | AK4: 0 | AM4: 멧자 | AO4: 아카시아APP
H5: Bale | I5: 중량 | J5: Bale | K5: 중량 | L5: Bale | M5: 중량 | N5: Bale | O5: 중량 | P5: Bale | Q5: 중량 | R5: Bale | S5: 중량 | T5: Bale | U5: 중량 | V5: Bale | W5: 중량 | X5: Bale | Y5: 중량 | Z5: 합계 | AA5: 배합비 | AB5: 합계 | AC5: 배합비 | AD5: 합계 | AE5: 배합비 | AK5: 0 | AM5: PCMC | AO5: Santafe
B6: LBKP | C6: Guaiba | D6: 247 | G6: =SUM(Z6,AB6,AD6) -> 0 | I6: =H6*D6 -> 0 | K6: =D6*J6 -> 0 | M6: =D6*L6 -> 0 | O6: =D6*N6 -> 0 | Q6: =D6*P6 -> 0 | S6: =D6*R6 -> 0 | U6: =D6*T6 -> 0 | W6: =D6*V6 -> 0 | Y6: =D6*X6 -> 0 | Z6: =SUM(I6,O6,U6) -> 0 | AA6: =IFERROR(Z10/Z16,"") | AB6: =SUM(K6,Q6,W6) -> 0 | AC6: =IFERROR(AB10/AB16,"") | AD6: =SUM(M6,S6,Y6) -> 0 | AE6: =IFERROR(AD10/AD16,"") | AF6: 비데원지 | AM6: Pacifico | AO6: Guaiba
C7: WET(LBKP) | D7: 137 | G7: =SUM(Z7,AB7,AD7) -> 0 | I7: =H7*D7 -> 0 | K7: =D7*J7 -> 0 | M7: =D7*L7 -> 0 | O7: =D7*N7 -> 0 | Q7: =D7*P7 -> 0 | S7: =D7*R7 -> 0 | U7: =D7*T7 -> 0 | W7: =D7*V7 -> 0 | Y7: =D7*X7 -> 0 | Z7: =SUM(I7,O7,U7) -> 0 | AB7: =SUM(K7,Q7,W7) -> 0 | AD7: =SUM(M7,S7,Y7) -> 0 | AF7: 미용티슈 | AM7: Ilimsk | AO7: WET(LBKP)
C8: Acacia | D8: 250 | G8: =SUM(Z8,AB8,AD8) -> 0 | I8: =H8*D8 -> 0 | K8: =D8*J8 -> 0 | M8: =D8*L8 -> 0 | O8: =D8*N8 -> 0 | Q8: =D8*P8 -> 0 | S8: =D8*R8 -> 0 | U8: =D8*T8 -> 0 | W8: =D8*V8 -> 0 | Y8: =D8*X8 -> 0 | Z8: =SUM(I8,O8,U8) -> 0 | AB8: =SUM(K8,Q8,W8) -> 0 | AD8: =SUM(M8,S8,Y8) -> 0 | AF8: 3R | AM8: 크라프튼 | AO8: 0
C9: 수자노 | D9: 249 | G9: =SUM(Z9,AB9,AD9) -> 0 | I9: =H9*D9 -> 0 | K9: =D9*J9 -> 0 | M9: =D9*L9 -> 0 | O9: =D9*N9 -> 0 | Q9: =D9*P9 -> 0 | S9: =D9*R9 -> 0 | U9: =D9*T9 -> 0 | W9: =D9*V9 -> 0 | Y9: =D9*X9 -> 0 | Z9: =SUM(I9,O9,U9) -> 0 | AB9: =SUM(K9,Q9,W9) -> 0 | AD9: =SUM(M9,S9,Y9) -> 0 | AM9: 비랄 | AO9: 0
C10: 소계 | E10: =SUM(E6:E9) -> 0 | F10: =SUM(F6:F9) -> 0 | G10: =SUM(G6:G9) -> 0 | I10: =SUM(I6:I9) -> 0 | K10: =SUM(K6:K9) -> 0 | M10: =SUM(M6:M9) -> 0 | O10: =SUM(O6:O9) -> 0 | Q10: =SUM(Q6:Q9) -> 0 | S10: =SUM(S6:S9) -> 0 | U10: =SUM(U6:U9) -> 0 | W10: =SUM(W6:W9) -> 0 | Y10: =SUM(Y6:Y9) -> 0 | Z10: =SUM(Z6:Z9) -> 0 | AB10: =SUM(AB6:AB9) -> 0 | AD10: =SUM(AD6:AD9) -> 0 | AM10: Arauco | AO10: 0
B11: NBKP | C11: 피스리버 | G11: =SUM(Z11,AB11,AD11) -> 0 | I11: =H11*D11 -> 0 | K11: =D11*J11 -> 0 | M11: =D11*L11 -> 0 | O11: =D11*N11 -> 0 | Q11: =D11*P11 -> 0 | S11: =D11*R11 -> 0 | U11: =D11*T11 -> 0 | W11: =D11*V11 -> 0 | Y11: =D11*X11 -> 0 | Z11: =SUM(I11,O11,U11) -> 0 | AA11: =IFERROR(1-AA6,"") | AB11: =SUM(K11,Q11,W11) -> 0 | AC11: =IFERROR(1-AC6,"") | AD11: =SUM(M11,S11,Y11) -> 0 | AE11: =IFERROR(1-AE6,"") | AM11: 하우사운드
C12: Ilimsk | G12: =SUM(Z12,AB12,AD12) -> 0 | I12: =H12*D12 -> 0 | K12: =D12*J12 -> 0 | M12: =D12*L12 -> 0 | O12: =D12*N12 -> 0 | Q12: =D12*P12 -> 0 | S12: =D12*R12 -> 0 | U12: =D12*T12 -> 0 | W12: =D12*V12 -> 0 | Y12: =D12*X12 -> 0 | Z12: =SUM(I12,O12,U12) -> 0 | AB12: =SUM(K12,Q12,W12) -> 0 | AD12: =SUM(M12,S12,Y12) -> 0 | AM12: 일림
C13: 멧자 | D13: 249 | G13: =SUM(Z13,AB13,AD13) -> 0 | I13: =H13*D13 -> 0 | K13: =D13*J13 -> 0 | M13: =D13*L13 -> 0 | O13: =D13*N13 -> 0 | Q13: =D13*P13 -> 0 | S13: =D13*R13 -> 0 | U13: =D13*T13 -> 0 | W13: =D13*V13 -> 0 | Y13: =D13*X13 -> 0 | Z13: =SUM(I13,O13,U13) -> 0 | AB13: =SUM(K13,Q13,W13) -> 0 | AD13: =SUM(M13,S13,Y13) -> 0 | AM13: 피스리버
C14: WET PULP | D14: 150 | G14: =SUM(Z14,AB14,AD14) -> 0 | I14: =H14*D14 -> 0 | K14: =D14*J14 -> 0 | M14: =D14*L14 -> 0 | O14: =D14*N14 -> 0 | Q14: =D14*P14 -> 0 | S14: =D14*R14 -> 0 | U14: =D14*T14 -> 0 | W14: =D14*V14 -> 0 | Y14: =D14*X14 -> 0 | Z14: =SUM(I14,O14,U14) -> 0 | AB14: =SUM(K14,Q14,W14) -> 0 | AD14: =SUM(M14,S14,Y14) -> 0
C15: 소계 | E15: =SUM(E11:E14) -> 0 | F15: =SUM(F11:F14) -> 0 | G15: =SUM(G11:G14) -> 0 | I15: =SUM(I11:I14) -> 0 | K15: =SUM(K11:K14) -> 0 | M15: =SUM(M11:M14) -> 0 | O15: =SUM(O11:O14) -> 0 | Q15: =SUM(Q11:Q14) -> 0 | S15: =SUM(S11:S14) -> 0 | U15: =SUM(U11:U14) -> 0 | W15: =SUM(W11:W14) -> 0 | Y15: =SUM(Y11:Y14) -> 0 | Z15: =SUM(Z11:Z14) -> 0 | AB15: =SUM(AB11:AB14) -> 0 | AD15: =SUM(AD11:AD14) -> 0
B16: 펄프 합계 | E16: =SUM(E15,E10) -> 0 | F16: =SUM(F15,F10) -> 0 | G16: =SUM(G10,G15) -> 0 | H16: =SUM(H15,H10) -> 0 | I16: =SUM(I15,I10) -> 0 | J16: =SUM(J15,J10) -> 0 | K16: =SUM(K15,K10) -> 0 | L16: =SUM(L15,L10) -> 0 | M16: =SUM(M15,M10) -> 0 | N16: =SUM(N15,N10) -> 0 | O16: =SUM(O15,O10) -> 0 | ... Z16: =SUM(Z15,Z10) -> 0 | AB16: =SUM(AB15,AB10) -> 0 | AD16: =SUM(AD15,AD10) -> 0
B27: 2. 원료 관리 현황
B28: 구분 | D28: 펄프 종류 | G28: N-PULP(Soft Wood) | Q28: L-PULP(Hard Wood) | AA28: 비고
D29: 브랜드 명 | G29: 피스리버 | I29: 멧자 | M29: 일림 | O29: WET PULP | S29: Guaiba | U29: 수자노 | W29: WET(LBKP) | Y29: 아카시아APP
D30: 전일 이월량 | G30: ='7'!G42:H42 -> 0 | I30: ='7'!I42:J42 -> 23 | K30: ='7'!K42:L42 -> 0 | M30: ='7'!M42:N42 -> 0 | O30: ='7'!O42:P42 -> 0 | Q30: ='7'!Q42:R42 -> 0 | S30: ='7'!S42:T42 -> 0 | U30: ='7'!U42:V42 -> 0 | W30: ='7'!W42:X42 -> 0 | Y30: ='7'!Y42:Z42 -> 150
B31: 오전 | D31: 입고량
D32: 사용량
D33: 재고량
B34: 오후 | D34: 입고량
D35: 사용량
D36: 재고량
B37: 야간 | D37: 입고량
D38: 사용량
D39: 재고량
B40: 펄프 합계 | D40: 총 사용량 | G40: =SUM(G32,G35,G38) -> 0 | I40: =SUM(I32,I35,I38) -> 0 | K40: =SUM(K32,K35,K38) -> 0 | M40: =SUM(M32,M35,M38) -> 0 | O40: =SUM(O32,O35,O38) -> 0 | Q40: =SUM(Q32,Q35,Q38) -> 0 | S40: =SUM(S32,S35,S38) -> 0 | U40: =SUM(U32,U35,U38) -> 0 | W40: =SUM(W32,W35,W38) -> 0 | Y40: =SUM(Y32,Y35,Y38) -> 0
D41: 총 거래 수량 | G41: =SUM(G30,G31,G34,G37) -> 0 | I41: =SUM(I30,I31,I34,I37) -> 23 | K41: =SUM(K30,K31,K34,K37) -> 0 | M41: =SUM(M30,M31,M34,M37) -> 0 | O41: =SUM(O30,O31,O34,O37) -> 0 | Q41: =SUM(Q30,Q31,Q34,Q37) -> 0 | S41: =SUM(S30,S31,S34,S37) -> 0 | U41: =SUM(U30,U31,U34,U37) -> 0 | W41: =SUM(W30,W31,W34,W37) -> 0 | Y41: =SUM(Y30,Y31,Y34,Y37) -> 150
D42: 재고량 | G42: =G41-G40 -> 0 | I42: =I41-I40 -> 23 | K42: =K41-K40 -> 0 | M42: =M41-M40 -> 0 | O42: =O41-O40 -> 0 | Q42: =Q41-Q40 -> 0 | S42: =S41-S40 -> 0 | U42: =U41-U40 -> 0 | W42: =W41-W40 -> 0 | Y42: =Y41-Y40 -> 150

Sheet 9
B1: ◈ 원질4호기 원료처리 작업 일지 | AM1: NBKP | AO1: LBKP
B2: 1. 원료 처리 현황 | Z2: 2026 년 01 월 09 일 | AK2: 데코 | AM2: 브라츠크 | AO2: Acacia
B3: 구분 | D3: 기준 중량 (kg) | E3: 전일 재공량 | F3: 금일 재공량 | G3: 일 원료 처리량 | H3: 오전( 반) | N3: 오후( 반) | T3: 야간( 반) | Z3: 합계 | AK3: K/T | AM3: WET PULP | AO3: 수자노
H4: 데코 | N4: 데코 | T4: 데코 | Z4: 데코 | AK4: 0 | AM4: 멧자 | AO4: 아카시아APP
H5: Bale | I5: 중량 | J5: Bale | K5: 중량 | L5: Bale | M5: 중량 | N5: Bale | O5: 중량 | P5: Bale | Q5: 중량 | R5: Bale | S5: 중량 | T5: Bale | U5: 중량 | V5: Bale | W5: 중량 | X5: Bale | Y5: 중량 | Z5: 합계 | AA5: 배합비 | AB5: 합계 | AC5: 배합비 | AD5: 합계 | AE5: 배합비 | AK5: 0 | AM5: PCMC | AO5: Santafe
B6: LBKP | C6: Guaiba | D6: 247 | G6: =SUM(Z6,AB6,AD6) -> 0 | I6: =H6*D6 -> 0 | K6: =D6*J6 -> 0 | M6: =D6*L6 -> 0 | O6: =D6*N6 -> 0 | Q6: =D6*P6 -> 0 | S6: =D6*R6 -> 0 | U6: =D6*T6 -> 0 | W6: =D6*V6 -> 0 | Y6: =D6*X6 -> 0 | Z6: =SUM(I6,O6,U6) -> 0 | AA6: =IFERROR(Z10/Z16,"") -> 0.88761847 | AB6: =SUM(K6,Q6,W6) -> 0 | AC6: =IFERROR(AB10/AB16,"") | AD6: =SUM(M6,S6,Y6) -> 0 | AE6: =IFERROR(AD10/AD16,"") | AF6: 비데원지 | AM6: Pacifico | AO6: Guaiba
C7: WET(LBKP) | D7: 137 | G7: =SUM(Z7,AB7,AD7) -> 0 | I7: =H7*D7 -> 0 | K7: =D7*J7 -> 0 | M7: =D7*L7 -> 0 | O7: =D7*N7 -> 0 | Q7: =D7*P7 -> 0 | S7: =D7*R7 -> 0 | U7: =D7*T7 -> 0 | W7: =D7*V7 -> 0 | Y7: =D7*X7 -> 0 | Z7: =SUM(I7,O7,U7) -> 0 | AB7: =SUM(K7,Q7,W7) -> 0 | AD7: =SUM(M7,S7,Y7) -> 0 | AF7: 미용티슈 | AM7: Ilimsk | AO7: WET(LBKP)
C8: Acacia | D8: 250 | G8: =SUM(Z8,AB8,AD8) -> 29500 | I8: =H8*D8 -> 0 | K8: =D8*J8 -> 0 | M8: =D8*L8 -> 0 | N8: 70 | O8: =D8*N8 -> 17500 | Q8: =D8*P8 -> 0 | S8: =D8*R8 -> 0 | T8: 48 | U8: =D8*T8 -> 12000 | W8: =D8*V8 -> 0 | Y8: =D8*X8 -> 0 | Z8: =SUM(I8,O8,U8) -> 29500 | AB8: =SUM(K8,Q8,W8) -> 0 | AD8: =SUM(M8,S8,Y8) -> 0 | AF8: 3R | AM8: 크라프튼 | AO8: 0
C9: 수자노 | D9: 249 | G9: =SUM(Z9,AB9,AD9) -> 0 | I9: =H9*D9 -> 0 | K9: =D9*J9 -> 0 | M9: =D9*L9 -> 0 | O9: =D9*N9 -> 0 | Q9: =D9*P9 -> 0 | S9: =D9*R9 -> 0 | U9: =D9*T9 -> 0 | W9: =D9*V9 -> 0 | Y9: =D9*X9 -> 0 | Z9: =SUM(I9,O9,U9) -> 0 | AB9: =SUM(K9,Q9,W9) -> 0 | AD9: =SUM(M9,S9,Y9) -> 0 | AM9: 비랄 | AO9: 0
C10: 소계 | E10: =SUM(E6:E9) -> 0 | F10: =SUM(F6:F9) -> 0 | G10: =SUM(G6:G9) -> 29500 | I10: =SUM(I6:I9) -> 0 | K10: =SUM(K6:K9) -> 0 | M10: =SUM(M6:M9) -> 0 | O10: =SUM(O6:O9) -> 17500 | Q10: =SUM(Q6:Q9) -> 0 | S10: =SUM(S6:S9) -> 0 | U10: =SUM(U6:U9) -> 12000 | W10: =SUM(W6:W9) -> 0 | Y10: =SUM(Y6:Y9) -> 0 | Z10: =SUM(Z6:Z9) -> 29500 | AB10: =SUM(AB6:AB9) -> 0 | AD10: =SUM(AD6:AD9) -> 0 | AM10: Arauco | AO10: 0
B11: NBKP | C11: 피스리버 | G11: =SUM(Z11,AB11,AD11) -> 0 | I11: =H11*D11 -> 0 | K11: =D11*J11 -> 0 | M11: =D11*L11 -> 0 | O11: =D11*N11 -> 0 | Q11: =D11*P11 -> 0 | S11: =D11*R11 -> 0 | U11: =D11*T11 -> 0 | W11: =D11*V11 -> 0 | Y11: =D11*X11 -> 0 | Z11: =SUM(I11,O11,U11) -> 0 | AA11: =IFERROR(1-AA6,"") -> 0.11238153 | AB11: =SUM(K11,Q11,W11) -> 0 | AC11: =IFERROR(1-AC6,"") | AD11: =SUM(M11,S11,Y11) -> 0 | AE11: =IFERROR(1-AE6,"") | AM11: 하우사운드
C12: Ilimsk | G12: =SUM(Z12,AB12,AD12) -> 0 | I12: =H12*D12 -> 0 | K12: =D12*J12 -> 0 | M12: =D12*L12 -> 0 | O12: =D12*N12 -> 0 | Q12: =D12*P12 -> 0 | S12: =D12*R12 -> 0 | U12: =D12*T12 -> 0 | W12: =D12*V12 -> 0 | Y12: =D12*X12 -> 0 | Z12: =SUM(I12,O12,U12) -> 0 | AB12: =SUM(K12,Q12,W12) -> 0 | AD12: =SUM(M12,S12,Y12) -> 0 | AM12: 일림
C13: 멧자 | D13: 249 | G13: =SUM(Z13,AB13,AD13) -> 3735 | I13: =H13*D13 -> 0 | K13: =D13*J13 -> 0 | M13: =D13*L13 -> 0 | N13: 9 | O13: =D13*N13 -> 2241 | Q13: =D13*P13 -> 0 | S13: =D13*R13 -> 0 | T13: 6 | U13: =D13*T13 -> 1494 | W13: =D13*V13 -> 0 | Y13: =D13*X13 -> 0 | Z13: =SUM(I13,O13,U13) -> 3735 | AB13: =SUM(K13,Q13,W13) -> 0 | AD13: =SUM(M13,S13,Y13) -> 0 | AM13: 피스리버
C14: WET PULP | D14: 150 | G14: =SUM(Z14,AB14,AD14) -> 0 | I14: =H14*D14 -> 0 | K14: =D14*J14 -> 0 | M14: =D14*L14 -> 0 | O14: =D14*N14 -> 0 | Q14: =D14*P14 -> 0 | S14: =D14*R14 -> 0 | U14: =D14*T14 -> 0 | W14: =D14*V14 -> 0 | Y14: =D14*X14 -> 0 | Z14: =SUM(I14,O14,U14) -> 0 | AB14: =SUM(K14,Q14,W14) -> 0 | AD14: =SUM(M14,S14,Y14) -> 0
C15: 소계 | E15: =SUM(E11:E14) -> 0 | F15: =SUM(F11:F14) -> 0 | G15: =SUM(G11:G14) -> 3735 | I15: =SUM(I11:I14) -> 0 | K15: =SUM(K11:K14) -> 0 | M15: =SUM(M11:M14) -> 0 | O15: =SUM(O11:O14) -> 2241 | Q15: =SUM(Q11:Q14) -> 0 | S15: =SUM(S11:S14) -> 0 | U15: =SUM(U11:U14) -> 1494 | W15: =SUM(W11:W14) -> 0 | Y15: =SUM(Y11:Y14) -> 0 | Z15: =SUM(Z11:Z14) -> 3735 | AB15: =SUM(AB11:AB14) -> 0 | AD15: =SUM(AD11:AD14) -> 0
B16: 펄프 합계 | E16: =SUM(E15,E10) -> 0 | F16: =SUM(F15,F10) -> 0 | G16: =SUM(G10,G15) -> 33235 | H16: =SUM(H15,H10) -> 0 | I16: =SUM(I15,I10) -> 0 | J16: =SUM(J15,J10) -> 0 | K16: =SUM(K15,K10) -> 0 | L16: =SUM(L15,L10) -> 0 | M16: =SUM(M15,M10) -> 0 | N16: =SUM(N15,N10) -> 0 | O16: =SUM(O15,O10) -> 19741 | ... Z16: =SUM(Z15,Z10) -> 33235 | AB16: =SUM(AB15,AB10) -> 0 | AD16: =SUM(AD15,AD10) -> 0
B27: 2. 원료 관리 현황
B28: 구분 | D28: 펄프 종류 | G28: N-PULP(Soft Wood) | Q28: L-PULP(Hard Wood) | AA28: 비고
D29: 브랜드 명 | G29: 피스리버 | I29: 멧자 | M29: 일림 | O29: WET PULP | S29: Guaiba | U29: 수자노 | W29: WET(LBKP) | Y29: 아카시아APP
D30: 전일 이월량 | G30: ='8'!G42:H42 -> 0 | I30: ='8'!I42:J42 -> 23 | K30: ='8'!K42:L42 -> 0 | M30: ='8'!M42:N42 -> 0 | O30: ='8'!O42:P42 -> 0 | Q30: ='8'!Q42:R42 -> 0 | S30: ='8'!S42:T42 -> 0 | U30: ='8'!U42:V42 -> 0 | W30: ='8'!W42:X42 -> 0 | Y30: ='8'!Y42:Z42 -> 150
B31: 오전 | D31: 입고량 | I31: 7 | Y31: 53
D32: 사용량
D33: 재고량
B34: 오후 | D34: 입고량
D35: 사용량 | I35: 9 | Y35: 70
D36: 재고량
B37: 야간 | D37: 입고량
D38: 사용량 | I38: 6 | Y38: 48
D39: 재고량 | I39: 15 | Y39: 85
B40: 펄프 합계 | D40: 총 사용량 | G40: =SUM(G32,G35,G38) -> 0 | I40: =SUM(I32,I35,I38) -> 15 | K40: =SUM(K32,K35,K38) -> 0 | M40: =SUM(M32,M35,M38) -> 0 | O40: =SUM(O32,O35,O38) -> 0 | Q40: =SUM(Q32,Q35,Q38) -> 0 | S40: =SUM(S32,S35,S38) -> 0 | U40: =SUM(U32,U35,U38) -> 0 | W40: =SUM(W32,W35,W38) -> 0 | Y40: =SUM(Y32,Y35,Y38) -> 118
D41: 총 거래 수량 | G41: =SUM(G30,G31,G34,G37) -> 0 | I41: =SUM(I30,I31,I34,I37) -> 30 | K41: =SUM(K30,K31,K34,K37) -> 0 | M41: =SUM(M30,M31,M34,M37) -> 0 | O41: =SUM(O30,O31,O34,O37) -> 0 | Q41: =SUM(Q30,Q31,Q34,Q37) -> 0 | S41: =SUM(S30,S31,S34,S37) -> 0 | U41: =SUM(U30,U31,U34,U37) -> 0 | W41: =SUM(W30,W31,W34,W37) -> 0 | Y41: =SUM(Y30,Y31,Y34,Y37) -> 203
D42: 재고량 | G42: =G41-G40 -> 0 | I42: =I41-I40 -> 15 | K42: =K41-K40 -> 0 | M42: =M41-M40 -> 0 | O42: =O41-O40 -> 0 | Q42: =Q41-Q40 -> 0 | S42: =S41-S40 -> 0 | U42: =U41-U40 -> 0 | W42: =W41-W40 -> 0 | Y42: =Y41-Y40 -> 85

Sheet 10
B1: ◈ 원질4호기 원료처리 작업 일지 | AM1: NBKP | AO1: LBKP
B2: 1. 원료 처리 현황 | Z2: 2026 년 01 월 10 일 | AK2: 데코 | AM2: 브라츠크 | AO2: Acacia
B3: 구분 | D3: 기준 중량 (kg) | E3: 전일 재공량 | F3: 금일 재공량 | G3: 일 원료 처리량 | H3: 오전( 반) | N3: 오후( 반) | T3: 야간( 반) | Z3: 합계 | AK3: K/T | AM3: WET PULP | AO3: 수자노
H4: 데코 | N4: 데코 | T4: 데코 | Z4: 데코 | AK4: 0 | AM4: 멧자 | AO4: 아카시아APP
H5: Bale | I5: 중량 | J5: Bale | K5: 중량 | L5: Bale | M5: 중량 | N5: Bale | O5: 중량 | P5: Bale | Q5: 중량 | R5: Bale | S5: 중량 | T5: Bale | U5: 중량 | V5: Bale | W5: 중량 | X5: Bale | Y5: 중량 | Z5: 합계 | AA5: 배합비 | AB5: 합계 | AC5: 배합비 | AD5: 합계 | AE5: 배합비 | AK5: 0 | AM5: PCMC | AO5: Santafe
B6: LBKP | C6: Guaiba | D6: 247 | G6: =SUM(Z6,AB6,AD6) -> 0 | I6: =H6*D6 -> 0 | K6: =D6*J6 -> 0 | M6: =D6*L6 -> 0 | O6: =D6*N6 -> 0 | Q6: =D6*P6 -> 0 | S6: =D6*R6 -> 0 | U6: =D6*T6 -> 0 | W6: =D6*V6 -> 0 | Y6: =D6*X6 -> 0 | Z6: =SUM(I6,O6,U6) -> 0 | AA6: =IFERROR(Z10/Z16,"") -> 0.90088203 | AB6: =SUM(K6,Q6,W6) -> 0 | AC6: =IFERROR(AB10/AB16,"") | AD6: =SUM(M6,S6,Y6) -> 0 | AE6: =IFERROR(AD10/AD16,"") | AF6: 비데원지 | AM6: Pacifico | AO6: Guaiba
C7: WET(LBKP) | D7: 137 | G7: =SUM(Z7,AB7,AD7) -> 0 | I7: =H7*D7 -> 0 | K7: =D7*J7 -> 0 | M7: =D7*L7 -> 0 | O7: =D7*N7 -> 0 | Q7: =D7*P7 -> 0 | S7: =D7*R7 -> 0 | U7: =D7*T7 -> 0 | W7: =D7*V7 -> 0 | Y7: =D7*X7 -> 0 | Z7: =SUM(I7,O7,U7) -> 0 | AB7: =SUM(K7,Q7,W7) -> 0 | AD7: =SUM(M7,S7,Y7) -> 0 | AF7: 미용티슈 | AM7: Ilimsk | AO7: WET(LBKP)
C8: Acacia | D8: 250 | G8: =SUM(Z8,AB8,AD8) -> 43000 | H8: 48 | I8: =H8*D8 -> 12000 | K8: =D8*J8 -> 0 | M8: =D8*L8 -> 0 | N8: 60 | O8: =D8*N8 -> 15000 | Q8: =D8*P8 -> 0 | S8: =D8*R8 -> 0 | T8: 64 | U8: =D8*T8 -> 16000 | W8: =D8*V8 -> 0 | Y8: =D8*X8 -> 0 | Z8: =SUM(I8,O8,U8) -> 43000 | AB8: =SUM(K8,Q8,W8) -> 0 | AD8: =SUM(M8,S8,Y8) -> 0 | AF8: 3R | AM8: 크라프튼 | AO8: 0
C9: 수자노 | D9: 249 | G9: =SUM(Z9,AB9,AD9) -> 0 | I9: =H9*D9 -> 0 | K9: =D9*J9 -> 0 | M9: =D9*L9 -> 0 | O9: =D9*N9 -> 0 | Q9: =D9*P9 -> 0 | S9: =D9*R9 -> 0 | U9: =D9*T9 -> 0 | W9: =D9*V9 -> 0 | Y9: =D9*X9 -> 0 | Z9: =SUM(I9,O9,U9) -> 0 | AB9: =SUM(K9,Q9,W9) -> 0 | AD9: =SUM(M9,S9,Y9) -> 0 | AM9: 비랄 | AO9: 0
C10: 소계 | E10: =SUM(E6:E9) -> 0 | F10: =SUM(F6:F9) -> 0 | G10: =SUM(G6:G9) -> 43000 | I10: =SUM(I6:I9) -> 12000 | K10: =SUM(K6:K9) -> 0 | M10: =SUM(M6:M9) -> 0 | O10: =SUM(O6:O9) -> 15000 | Q10: =SUM(Q6:Q9) -> 0 | S10: =SUM(S6:S9) -> 0 | U10: =SUM(U6:U9) -> 16000 | W10: =SUM(W6:W9) -> 0 | Y10: =SUM(Y6:Y9) -> 0 | Z10: =SUM(Z6:Z9) -> 43000 | AB10: =SUM(AB6:AB9) -> 0 | AD10: =SUM(AD6:AD9) -> 0 | AM10: Arauco | AO10: 0
B11: NBKP | C11: 피스리버 | G11: =SUM(Z11,AB11,AD11) -> 0 | I11: =H11*D11 -> 0 | K11: =D11*J11 -> 0 | M11: =D11*L11 -> 0 | O11: =D11*N11 -> 0 | Q11: =D11*P11 -> 0 | S11: =D11*R11 -> 0 | U11: =D11*T11 -> 0 | W11: =D11*V11 -> 0 | Y11: =D11*X11 -> 0 | Z11: =SUM(I11,O11,U11) -> 0 | AA11: =IFERROR(1-AA6,"") -> 0.099117974 | AB11: =SUM(K11,Q11,W11) -> 0 | AC11: =IFERROR(1-AC6,"") | AD11: =SUM(M11,S11,Y11) -> 0 | AE11: =IFERROR(1-AE6,"") | AM11: 하우사운드
C12: Ilimsk | G12: =SUM(Z12,AB12,AD12) -> 0 | I12: =H12*D12 -> 0 | K12: =D12*J12 -> 0 | M12: =D12*L12 -> 0 | O12: =D12*N12 -> 0 | Q12: =D12*P12 -> 0 | S12: =D12*R12 -> 0 | U12: =D12*T12 -> 0 | W12: =D12*V12 -> 0 | Y12: =D12*X12 -> 0 | Z12: =SUM(I12,O12,U12) -> 0 | AB12: =SUM(K12,Q12,W12) -> 0 | AD12: =SUM(M12,S12,Y12) -> 0 | AM12: 일림
